Workbook
Name Air_Freight_Result_LU: #REF!
Name Air_Frieght_Unique_Names: #REF!
Name Calcs_Lookup: #REF!
Name Calcs_Lookup: #REF!
Name Calcs_Lookup: '[1]Array Names'!$A$76:$D$82
Name Calculations: #REF!
Name Calculations: #REF!
Name Calculations: '[2]Air Travel'!$C$47:$C$48
Name Chilled: #REF!
Name Chilled: #REF!
Name Chilled: '[1]Sea Backend'!$A$52
Name CO2perGJ_jet: #REF!
Name Cooking_Results_LU: #REF!
Name Cooking_Unique_Name: #REF!
Name DB_DG_Col2: #REF!
Name DB_DG_Col2: #REF!
Name DB_DG_Col2: '[1]CarbonTrust Database'!$BG:$BG
Name DB_DG_Start2: #REF!
Name DB_DG_Start2: #REF!
Name DB_DG_Start2: '[1]CarbonTrust Database'!$BG$1
Name DB_Lookup: #REF!
Name DB_Lookup: #REF!
Name DB_Lookup: '[1]CarbonTrust Database'!$F:$H
Name DomRefrig_Results_LU: #REF!
Name DomRefrig_Unique: #REF!
Name EF_custom: #REF!
Name Ef_for_km: #REF!
Name Ef_for_mile: #REF!
Name Eol_Qs_LU: #REF!
Name Eol_Qs_LU: #REF!
Name Eol_Qs_LU: '[1]EoL Backend'!$D$41:$E$42
Name EOL_Region_LU: #REF!
Name EOL_Region_LU: #REF!
Name EOL_Region_LU: '[1]EoL Backend'!$C$209:$H$213
Name EOL_Results_LU: #REF!
Name EOL_Unique: #REF!
Name EOL_Unique_Name: #REF!
Name EOL_Unique2: #REF!
Name EOL_Unique3: #REF!
Name Fleet_data: #REF!
Name Fleet_data: #REF!
Name Fleet_data: '[1]Road BACKEND'!$F$118
Name Footprint_Unique_Name: #REF!
Name FPXC: #REF!
Name FPXC: #REF!
Name FPXC: '[1]Array Names'!$A$19
Name Frozen: #REF!
Name Frozen: #REF!
Name Frozen: '[1]Sea Backend'!$A$53
Name FX_DB_lookups: #REF!
Name FX_DB_lookups: #REF!
Name FX_DB_lookups: '[1]CarbonTrust Database'!$F:$H
Name fxdb: #REF!
Name get_dieselgperkm: #REF!
Name get_dieselgperkm: #REF!
Name get_dieselgperkm: [3]Reference!$E$196:$J$259
Name get_gasgperkm: #REF!
Name get_gasgperkm: #REF!
Name get_gasgperkm: [3]Reference!$E$196:$I$259
Name Gjperton_jet: #REF!

Sheet Carbon seq model
D1: New Forests Company: Combined carbon sequestration model.
D2: Version: | E2: 1
D3: Date: | E3: 28 July 2025
D4: Last update by: | E4: T Knowles
D6: Model inputs
D7: Parameter | E7: Value | F7: Source
D8: VCS Risk discount (%) | E8: 0.18 | F8: Verra Risk Tool (attached)
D10: Conservation Area Woody Carbon Pool Model
D11: Spatial extent | E11: ='Project area'!C3 -> 3957 | F11: hectares
D12: Annual Aboveground Growth Rate (tC/ha.yr) | E12: 1.8 | F12: Wheeler et al. (2016)
D13: Root:shoot ratio | E13: 0.42 | F13: Mokany et al 2006
D15: CDM/Verra Soil Organic Carbon Model (see reference below)
D16: SOC sequetration rate (tC/ha.yr) | E16: 0.8 | F16: Meth Tool (First 20 years) | J16: =E16/0.5 -> 1.6
D18: Ratio of molecular weights
D19: Carbon to Carbon Dioxide | E19: =44/12 -> 3.6666667
D22: Carbon sequestration in tons of carbon per hectare
E23: 2017 | F23: =E23+1 -> 2018 | G23: =F23+1 -> 2019 | H23: =G23+1 -> 2020 | I23: =H23+1 -> 2021 | J23: =I23+1 -> 2022 | K23: =J23+1 -> 2023 | L23: =K23+1 -> 2024 | M23: =L23+1 -> 2025 | ... AR23: =AQ23+1 -> 2056
E24: Year 1 | F24: Year 2 | G24: Year 3 | H24: Year 4 | I24: Year 5 | J24: Year 6 | K24: Year 7 | L24: Year 8 | M24: Year 9 | N24: Year 10 | O24: Year 11 | P24: Year 12 | Q24: Year 13 | R24: Year 14 | S24: Year 15 | T24: Year 16 | U24: Year 17 | V24: Year 18 | W24: Year 19 | X24: Year 20 | Y24: Year 21 | Z24: Year 22 | AA24: Year 23 | AB24: Year 24 | AC24: Year 25 | AD24: Year 26 | AE24: Year 27 | AF24: Year 28 | AG24: Year 29 | AH24: Year 30 | AI24: Year 31 | AJ24: Year 32 | AK24: Year 33 | AL24: Year 34 | AM24: Year 35 | AN24: Year 36 | AO24: Year 37 | AP24: Year 38 | AQ24: Year 39 | AR24: Year 40
D26: Conservation Area
D28: Biomass carbon pool (tC/ha.yr)
D29: Total | E29: =($E$12*(1+$E$13))*$E$11 -> 10114.092 | F29: =($E$12*(1+$E$13))*$E$11 -> 10114.092 | G29: =($E$12*(1+$E$13))*$E$11 -> 10114.092 | H29: =($E$12*(1+$E$13))*$E$11 -> 10114.092 | I29: =($E$12*(1+$E$13))*$E$11 -> 10114.092 | J29: =($E$12*(1+$E$13))*$E$11 -> 10114.092 | K29: =($E$12*(1+$E$13))*$E$11 -> 10114.092 | L29: =($E$12*(1+$E$13))*$E$11 -> 10114.092 | ... AR29: =($E$12*(1+$E$13))*$E$11 -> 10114.092 | AT29: =SUM(E29:AR29) -> 404563.68
D31: Soil organic carbon pool (tC/ha.yr)
D32: Total | E32: =$E$16*$E$11 -> 3165.6 | F32: =$E$16*$E$11 -> 3165.6 | G32: =$E$16*$E$11 -> 3165.6 | H32: =$E$16*$E$11 -> 3165.6 | I32: =$E$16*$E$11 -> 3165.6 | J32: =$E$16*$E$11 -> 3165.6 | K32: =$E$16*$E$11 -> 3165.6 | L32: =$E$16*$E$11 -> 3165.6 | ... X32: =$E$16*$E$11 -> 3165.6 | Y32: 0 | Z32: 0 | AA32: 0 | AB32: 0 | AC32: 0 | AD32: 0 | AE32: 0 | AF32: 0 | AG32: 0 | AH32: 0 | AI32: 0 | AJ32: 0 | AK32: 0 | AL32: 0 | AM32: 0 | AN32: 0 | AO32: 0 | AP32: 0 | AQ32: 0 | AR32: 0 | AT32: =SUM(E32:AR32) -> 63312
D34: Out-grower ARR
D36: Biomass carbon pool (tC/ha.yr)
D37: Total | E37: ='Outgrower Woody C Pool'!G80 -> 905.82414 | F37: ='Outgrower Woody C Pool'!G81 -> 4669.4114 | G37: ='Outgrower Woody C Pool'!G82 -> 7408.8176 | H37: ='Outgrower Woody C Pool'!G83 -> 11652.462 | I37: ='Outgrower Woody C Pool'!G84 -> 14107.383 | J37: ='Outgrower Woody C Pool'!G85 -> 16182.457 | K37: ='Outgrower Woody C Pool'!G86 -> 17584.565 | L37: ='Outgrower Woody C Pool'!G87 -> 15344.537 | M37: ='Outgrower Woody C Pool'!G88 -> 0 | N37: ='Outgrower Woody C Pool'!G89 -> 6788.1716 | O37: ='Outgrower Woody C Pool'!G90 -> 0 | P37: ='Outgrower Woody C Pool'!G91 -> 22102.049 | Q37: ='Outgrower Woody C Pool'!G92 -> 18500.405 | R37: ='Outgrower Woody C Pool'!G93 -> 37726.58 | S37: ='Outgrower Woody C Pool'!G94 -> 10594.198 | T37: ='Outgrower Woody C Pool'!G95 -> 0 | AT37: =SUM(E37:AR37) -> 183566.86
D39: Soil organic carbon pool (tC/ha.yr)
B40: 2017 | C40: ='Outgrower Woody C Pool'!C80 -> 353.95 | E40: =$E$16*$C40 -> 283.16 | F40: =$E$16*$C40 -> 283.16 | G40: =$E$16*$C40 -> 283.16 | H40: =$E$16*$C40 -> 283.16 | I40: =$E$16*$C40 -> 283.16 | J40: =$E$16*$C40 -> 283.16 | K40: =$E$16*$C40 -> 283.16 | L40: =$E$16*$C40 -> 283.16 | ... X40: =$E$16*$C40 -> 283.16 | Y40: 0 | Z40: 0 | AA40: 0 | AB40: 0 | AC40: 0 | AD40: 0 | AE40: 0 | AF40: 0 | AG40: 0 | AH40: 0 | AI40: 0 | AJ40: 0 | AK40: 0 | AL40: 0 | AM40: 0 | AN40: 0 | AO40: 0 | AP40: 0 | AQ40: 0 | AR40: 0
B41: 2018 | C41: ='Outgrower Woody C Pool'!C81 -> 208.55 | F41: =$E$16*$C41 -> 166.84 | G41: =$E$16*$C41 -> 166.84 | H41: =$E$16*$C41 -> 166.84 | I41: =$E$16*$C41 -> 166.84 | J41: =$E$16*$C41 -> 166.84 | K41: =$E$16*$C41 -> 166.84 | L41: =$E$16*$C41 -> 166.84 | M41: =$E$16*$C41 -> 166.84 | ... Y41: =$E$16*$C41 -> 166.84 | Z41: 0 | AA41: 0 | AB41: 0 | AC41: 0 | AD41: 0 | AE41: 0 | AF41: 0 | AG41: 0 | AH41: 0 | AI41: 0 | AJ41: 0 | AK41: 0 | AL41: 0 | AM41: 0 | AN41: 0 | AO41: 0 | AP41: 0 | AQ41: 0 | AR41: 0
B42: 2019 | C42: ='Outgrower Woody C Pool'!C82 -> 244.22 | G42: =$E$16*$C42 -> 195.376 | H42: =$E$16*$C42 -> 195.376 | I42: =$E$16*$C42 -> 195.376 | J42: =$E$16*$C42 -> 195.376 | K42: =$E$16*$C42 -> 195.376 | L42: =$E$16*$C42 -> 195.376 | M42: =$E$16*$C42 -> 195.376 | N42: =$E$16*$C42 -> 195.376 | ... Z42: =$E$16*$C42 -> 195.376 | AA42: 0 | AB42: 0 | AC42: 0 | AD42: 0 | AE42: 0 | AF42: 0 | AG42: 0 | AH42: 0 | AI42: 0 | AJ42: 0 | AK42: 0 | AL42: 0 | AM42: 0 | AN42: 0 | AO42: 0 | AP42: 0 | AQ42: 0 | AR42: 0
B43: 2020 | C43: ='Outgrower Woody C Pool'!C83 -> 111.18 | H43: =$E$16*$C43 -> 88.944 | I43: =$E$16*$C43 -> 88.944 | J43: =$E$16*$C43 -> 88.944 | K43: =$E$16*$C43 -> 88.944 | L43: =$E$16*$C43 -> 88.944 | M43: =$E$16*$C43 -> 88.944 | N43: =$E$16*$C43 -> 88.944 | O43: =$E$16*$C43 -> 88.944 | ... AA43: =$E$16*$C43 -> 88.944 | AB43: 0 | AC43: 0 | AD43: 0 | AE43: 0 | AF43: 0 | AG43: 0 | AH43: 0 | AI43: 0 | AJ43: 0 | AK43: 0 | AL43: 0 | AM43: 0 | AN43: 0 | AO43: 0 | AP43: 0 | AQ43: 0 | AR43: 0
B44: 2021 | C44: ='Outgrower Woody C Pool'!C84 -> 143.59 | I44: =$E$16*$C44 -> 114.872 | J44: =$E$16*$C44 -> 114.872 | K44: =$E$16*$C44 -> 114.872 | L44: =$E$16*$C44 -> 114.872 | M44: =$E$16*$C44 -> 114.872 | N44: =$E$16*$C44 -> 114.872 | O44: =$E$16*$C44 -> 114.872 | P44: =$E$16*$C44 -> 114.872 | ... AB44: =$E$16*$C44 -> 114.872 | AC44: 0 | AD44: 0 | AE44: 0 | AF44: 0 | AG44: 0 | AH44: 0 | AI44: 0 | AJ44: 0 | AK44: 0 | AL44: 0 | AM44: 0 | AN44: 0 | AO44: 0 | AP44: 0 | AQ44: 0 | AR44: 0
B45: 2022 | C45: ='Outgrower Woody C Pool'!C85 -> 36.88 | J45: =$E$16*$C45 -> 29.504 | K45: =$E$16*$C45 -> 29.504 | L45: =$E$16*$C45 -> 29.504 | M45: =$E$16*$C45 -> 29.504 | N45: =$E$16*$C45 -> 29.504 | O45: =$E$16*$C45 -> 29.504 | P45: =$E$16*$C45 -> 29.504 | Q45: =$E$16*$C45 -> 29.504 | ... AC45: =$E$16*$C45 -> 29.504 | AD45: 0 | AE45: 0 | AF45: 0 | AG45: 0 | AH45: 0 | AI45: 0 | AJ45: 0 | AK45: 0 | AL45: 0 | AM45: 0 | AN45: 0 | AO45: 0 | AP45: 0 | AQ45: 0 | AR45: 0
B46: 2023 | C46: ='Outgrower Woody C Pool'!C86 -> 104.38 | K46: =$E$16*$C46 -> 83.504 | L46: =$E$16*$C46 -> 83.504 | M46: =$E$16*$C46 -> 83.504 | N46: =$E$16*$C46 -> 83.504 | O46: =$E$16*$C46 -> 83.504 | P46: =$E$16*$C46 -> 83.504 | Q46: =$E$16*$C46 -> 83.504 | R46: =$E$16*$C46 -> 83.504 | ... AD46: =$E$16*$C46 -> 83.504 | AE46: 0 | AF46: 0 | AG46: 0 | AH46: 0 | AI46: 0 | AJ46: 0 | AK46: 0 | AL46: 0 | AM46: 0 | AN46: 0 | AO46: 0 | AP46: 0 | AQ46: 0 | AR46: 0
B47: 2024 | C47: ='Outgrower Woody C Pool'!C87 -> 39.85 | L47: =$E$16*$C47 -> 31.88 | M47: =$E$16*$C47 -> 31.88 | N47: =$E$16*$C47 -> 31.88 | O47: =$E$16*$C47 -> 31.88 | P47: =$E$16*$C47 -> 31.88 | Q47: =$E$16*$C47 -> 31.88 | R47: =$E$16*$C47 -> 31.88 | S47: =$E$16*$C47 -> 31.88 | ... AE47: =$E$16*$C47 -> 31.88 | AF47: 0 | AG47: 0 | AH47: 0 | AI47: 0 | AJ47: 0 | AK47: 0 | AL47: 0 | AM47: 0 | AN47: 0 | AO47: 0 | AP47: 0 | AQ47: 0 | AR47: 0
B48: 2025 | C48: ='Outgrower Woody C Pool'!C88 -> 62.52 | M48: =$E$16*$C48 -> 50.016 | N48: =$E$16*$C48 -> 50.016 | O48: =$E$16*$C48 -> 50.016 | P48: =$E$16*$C48 -> 50.016 | Q48: =$E$16*$C48 -> 50.016 | R48: =$E$16*$C48 -> 50.016 | S48: =$E$16*$C48 -> 50.016 | T48: =$E$16*$C48 -> 50.016 | ... AF48: =$E$16*$C48 -> 50.016 | AG48: 0 | AH48: 0 | AI48: 0 | AJ48: 0 | AK48: 0 | AL48: 0 | AM48: 0 | AN48: 0 | AO48: 0 | AP48: 0 | AQ48: 0 | AR48: 0
B49: 2026 | C49: ='Outgrower Woody C Pool'!C89 -> 300 | N49: =$E$16*$C49 -> 240 | O49: =$E$16*$C49 -> 240 | P49: =$E$16*$C49 -> 240 | Q49: =$E$16*$C49 -> 240 | R49: =$E$16*$C49 -> 240 | S49: =$E$16*$C49 -> 240 | T49: =$E$16*$C49 -> 240 | U49: =$E$16*$C49 -> 240 | ... AG49: =$E$16*$C49 -> 240 | AH49: 0 | AI49: 0 | AJ49: 0 | AK49: 0 | AL49: 0 | AM49: 0 | AN49: 0 | AO49: 0 | AP49: 0 | AQ49: 0 | AR49: 0
B50: 2027 | C50: ='Outgrower Woody C Pool'!C90 -> 300 | O50: =$E$16*$C50 -> 240 | P50: =$E$16*$C50 -> 240 | Q50: =$E$16*$C50 -> 240 | R50: =$E$16*$C50 -> 240 | S50: =$E$16*$C50 -> 240 | T50: =$E$16*$C50 -> 240 | U50: =$E$16*$C50 -> 240 | V50: =$E$16*$C50 -> 240 | ... AH50: =$E$16*$C50 -> 240 | AI50: 0 | AJ50: 0 | AK50: 0 | AL50: 0 | AM50: 0 | AN50: 0 | AO50: 0 | AP50: 0 | AQ50: 0 | AR50: 0
B51: 2028 | C51: ='Outgrower Woody C Pool'!C91 -> 300 | P51: =$E$16*$C51 -> 240 | Q51: =$E$16*$C51 -> 240 | R51: =$E$16*$C51 -> 240 | S51: =$E$16*$C51 -> 240 | T51: =$E$16*$C51 -> 240 | U51: =$E$16*$C51 -> 240 | V51: =$E$16*$C51 -> 240 | W51: =$E$16*$C51 -> 240 | ... AI51: =$E$16*$C51 -> 240 | AJ51: 0 | AK51: 0 | AL51: 0 | AM51: 0 | AN51: 0 | AO51: 0 | AP51: 0 | AQ51: 0 | AR51: 0
B52: 2029 | C52: ='Outgrower Woody C Pool'!C92 -> 300 | Q52: =$E$16*$C52 -> 240 | R52: =$E$16*$C52 -> 240 | S52: =$E$16*$C52 -> 240 | T52: =$E$16*$C52 -> 240 | U52: =$E$16*$C52 -> 240 | V52: =$E$16*$C52 -> 240 | W52: =$E$16*$C52 -> 240 | X52: =$E$16*$C52 -> 240 | ... AJ52: =$E$16*$C52 -> 240 | AK52: 0 | AL52: 0 | AM52: 0 | AN52: 0 | AO52: 0 | AP52: 0 | AQ52: 0 | AR52: 0
...

Sheet Transposed PD tables
B2: Data transposed
B4: Year | C4: Estimated project emissions per year (tCO2e/yr) | D4: Buffer Pool allocation | E4: Removal VCUs per year (tCO2e/yr) | H4: Vintage Period | I4: Estimated baseline emissions (tCO2e) | J4: Estimated project emissions (tCO2e) | K4: Estimated leakage emissions (tCO2e) | L4: Estimated Buffer Pool allocation (tCO2e) | M4: Estimated reduction VCUs (tCO2e) | N4: Estimated removal VCUs (tCO2e) | O4: Estimated total VCUs (tCO2e/yr)
B5: 1 | C5: {=TRANSPOSE('Carbon seq model'!E77:AR77)} -> 53051.813 | D5: {=TRANSPOSE('Carbon seq model'!E79:AR79)} -> 9549.3263 | E5: =C5-D5 -> 43502.486 | H5: 1 July 2017 to 31 Dec 2017 | I5: 0 | J5: =C5 -> 53051.813 | K5: 0 | L5: =D5 -> 9549.3263 | M5: 0 | N5: =-I5+J5-K5-L5 -> 43502.486 | O5: =SUM(M5:N5) -> 43502.486
B6: 2 | C6: 67463.379 | D6: 12143.408 | E6: =C6-D6 -> 55319.971 | H6: 1 Jan 2018 to 31 Dec 2018 | I6: 0 | J6: =C6 -> 67463.379 | K6: 0 | L6: =D6 -> 12143.408 | M6: 0 | N6: =-I6+J6-K6-L6 -> 55319.971 | O6: =SUM(M6:N6) -> 55319.971
B7: 3 | C7: 78224.247 | D7: 14080.364 | E7: =C7-D7 -> 64143.883 | H7: 1 Jan 2019 to 31 Dec 2019 | I7: 0 | J7: =C7 -> 78224.247 | K7: 0 | L7: =D7 -> 14080.364 | M7: 0 | N7: =-I7+J7-K7-L7 -> 64143.883 | O7: =SUM(M7:N7) -> 64143.883
B8: 4 | C8: 94110.404 | D8: 16939.873 | E8: =C8-D8 -> 77170.532 | H8: 1 Jan 2020 to 31 Dec 2020 | I8: 0 | J8: =C8 -> 94110.404 | K8: 0 | L8: =D8 -> 16939.873 | M8: 0 | N8: =-I8+J8-K8-L8 -> 77170.532 | O8: =SUM(M8:N8) -> 77170.532
B9: 5 | C9: 103532.98 | D9: 18635.936 | E9: =C9-D9 -> 84897.044 | H9: 1 Jan 2021 to 31 Dec 2021 | I9: 0 | J9: =C9 -> 103532.98 | K9: 0 | L9: =D9 -> 18635.936 | M9: 0 | N9: =-I9+J9-K9-L9 -> 84897.044 | O9: =SUM(M9:N9) -> 84897.044
B10: 6 | C10: 111249.77 | D10: 20024.958 | E10: =C10-D10 -> 91224.809 | H10: 1 Jan 2022 to 31 Dec 2022 | I10: 0 | J10: =C10 -> 111249.77 | K10: 0 | L10: =D10 -> 20024.958 | M10: 0 | N10: =-I10+J10-K10-L10 -> 91224.809 | O10: =SUM(M10:N10) -> 91224.809
B11: 7 | C11: 116697.01 | D11: 21005.462 | E11: =C11-D11 -> 95691.548 | H11: 1 Jan 2023 to 31 Dec 2023 | I11: 0 | J11: =C11 -> 116697.01 | K11: 0 | L11: =D11 -> 21005.462 | M11: 0 | N11: =-I11+J11-K11-L11 -> 95691.548 | O11: =SUM(M11:N11) -> 95691.548
B12: 8 | C12: 108600.47 | D12: 19548.084 | E12: =C12-D12 -> 89052.384 | H12: 1 Jan 2024 to 31 Dec 2024 | I12: 0 | J12: =C12 -> 108600.47 | K12: 0 | L12: =D12 -> 19548.084 | M12: 0 | N12: =-I12+J12-K12-L12 -> 89052.384 | O12: =SUM(M12:N12) -> 89052.384
B13: 9 | C13: 52520.556 | D13: 9453.7001 | E13: =C13-D13 -> 43066.856 | H13: 1 Jan 2025 to 31 Dec 2025 | I13: 0 | J13: =C13 -> 52520.556 | K13: 0 | L13: =D13 -> 9453.7001 | M13: 0 | N13: =-I13+J13-K13-L13 -> 43066.856 | O13: =SUM(M13:N13) -> 43066.856
B14: 10 | C14: 78290.519 | D14: 14092.293 | E14: =C14-D14 -> 64198.225 | H14: 1 Jan 2026 to 31 Dec 2026 | I14: 0 | J14: =C14 -> 78290.519 | K14: 0 | L14: =D14 -> 14092.293 | M14: 0 | N14: =-I14+J14-K14-L14 -> 64198.225 | O14: =SUM(M14:N14) -> 64198.225
B15: 11 | C15: 54280.556 | D15: 9770.5001 | E15: =C15-D15 -> 44510.056 | H15: 1 Jan 2027 to 31 Dec 2027 | I15: 0 | J15: =C15 -> 54280.556 | K15: 0 | L15: =D15 -> 9770.5001 | M15: 0 | N15: =-I15+J15-K15-L15 -> 44510.056 | O15: =SUM(M15:N15) -> 44510.056
B16: 12 | C16: 136201.4 | D16: 24516.252 | E16: =C16-D16 -> 111685.15 | H16: 1 Jan 2028 to 31 Dec 2028 | I16: 0 | J16: =C16 -> 136201.4 | K16: 0 | L16: =D16 -> 24516.252 | M16: 0 | N16: =-I16+J16-K16-L16 -> 111685.15 | O16: =SUM(M16:N16) -> 111685.15
B17: 13 | C17: 123875.37 | D17: 22297.567 | E17: =C17-D17 -> 101577.81 | H17: 1 Jan 2029 to 31 Dec 2029 | I17: 0 | J17: =C17 -> 123875.37 | K17: 0 | L17: =D17 -> 22297.567 | M17: 0 | N17: =-I17+J17-K17-L17 -> 101577.81 | O17: =SUM(M17:N17) -> 101577.81
... B44: 40 | C44: 45885.004 | D44: 8259.3007 | E44: =C44-D44 -> 37625.703 | H44: 1 Jan 2056 to 31 Dec 2056 | I44: 0 | J44: =C44 -> 45885.004 | K44: 0 | L44: =D44 -> 8259.3007 | M44: 0 | N44: =-I44+J44-K44-L44 -> 37625.703 | O44: =SUM(M44:N44) -> 37625.703
B45: Total | C45: =SUM(C5:C44) -> 2795189.7 | D45: =SUM(D5:D44) -> 503134.14 | E45: =SUM(E5:E44) -> 2292055.5 | H45: TOTAL | I45: 0 | J45: =SUM(J5:J44) -> 2795189.7 | K45: =SUM(K5:K44) -> 0 | L45: =SUM(L5:L44) -> 503134.14 | M45: =SUM(M5:M44) -> 0 | N45: =SUM(N5:N44) -> 2292055.5 | O45: =SUM(O5:O44) -> 2292055.5
J47: =J45/COUNT(J5:J44) -> 69879.742

Sheet Project area
C1: Conservation areas
C2: New data
C3: 3957 | D3: hectares
C6: Outgrowers areas (Afforestation)
C7: New data (clean polygons +updated projections)
C8: Year | D8: Euc | E8: Pine | F8: Total | G8: Cumulative
B9: 1 | C9: =C10-1 -> 2017 | D9: 267.16 | E9: 86.79 | F9: =D9+E9 -> 353.95 | G9: =F9 -> 353.95 | I9: Actuals
B10: =B9+1 -> 2 | C10: =C11-1 -> 2018 | D10: 100.9 | E10: 107.65 | F10: =D10+E10 -> 208.55 | G10: =G9+F10 -> 562.5 | I10: Actuals
B11: =B10+1 -> 3 | C11: =C12-1 -> 2019 | D11: 243.04 | E11: 1.18 | F11: =D11+E11 -> 244.22 | G11: =G10+F11 -> 806.72 | I11: Actuals
B12: =B11+1 -> 4 | C12: =C13-1 -> 2020 | D12: 69.32 | E12: 41.86 | F12: =D12+E12 -> 111.18 | G12: =G11+F12 -> 917.9 | I12: Actuals
B13: =B12+1 -> 5 | C13: 2021 | D13: 142.3 | E13: 1.29 | F13: =D13+E13 -> 143.59 | G13: =G12+F13 -> 1061.49 | I13: Actuals
B14: =B13+1 -> 6 | C14: =C13+1 -> 2022 | D14: 35.19 | E14: 1.69 | F14: =D14+E14 -> 36.88 | G14: =G13+F14 -> 1098.37 | I14: Actuals
B15: =B14+1 -> 7 | C15: =C14+1 -> 2023 | D15: 95.61 | E15: 8.77 | F15: =D15+E15 -> 104.38 | G15: =G14+F15 -> 1202.75 | I15: Actuals
B16: =B15+1 -> 8 | C16: =C15+1 -> 2024 | D16: 36.41 | E16: 3.44 | F16: =D16+E16 -> 39.85 | G16: =G15+F16 -> 1242.6 | I16: Actuals
B17: =B16+1 -> 9 | C17: =C16+1 -> 2025 | D17: 62.52 | F17: =D17+E17 -> 62.52 | G17: =G16+F17 -> 1305.12 | I17: Actuals
B18: =B17+1 -> 10 | C18: =C17+1 -> 2026 | D18: 300 | F18: =D18+E18 -> 300 | G18: =G17+F18 -> 1605.12 | I18: Projections
B19: =B18+1 -> 11 | C19: =C18+1 -> 2027 | D19: 300 | F19: =D19+E19 -> 300 | G19: =G18+F19 -> 1905.12 | I19: Projections
B20: =B19+1 -> 12 | C20: =C19+1 -> 2028 | D20: 300 | F20: =D20+E20 -> 300 | G20: =G19+F20 -> 2205.12 | I20: Projections
B21: =B20+1 -> 13 | C21: =C20+1 -> 2029 | D21: 300 | F21: =D21+E21 -> 300 | G21: =G20+F21 -> 2505.12 | I21: Projections
B22: =B21+1 -> 14 | C22: =C21+1 -> 2030 | D22: 300 | F22: =D22+E22 -> 300 | G22: =G21+F22 -> 2805.12 | I22: Projections
B23: =B22+1 -> 15 | C23: =C22+1 -> 2031 | D23: 300 | F23: =D23+E23 -> 300 | G23: =G22+F23 -> 3105.12 | I23: Projections
B24: =B23+1 -> 16 | C24: =C23+1 -> 2032 | D24: 300 | F24: =D24+E24 -> 300 | G24: =G23+F24 -> 3405.12 | I24: Projections
B25: =B24+1 -> 17 | C25: =C24+1 -> 2033 | D25: 300 | F25: =D25+E25 -> 300 | G25: =G24+F25 -> 3705.12 | I25: Projections
B26: =B25+1 -> 18 | C26: =C25+1 -> 2034 | D26: 300 | F26: =D26+E26 -> 300 | G26: =G25+F26 -> 4005.12 | I26: Projections
B27: =B26+1 -> 19 | C27: =C26+1 -> 2035 | D27: 300 | F27: =D27+E27 -> 300 | G27: =G26+F27 -> 4305.12 | I27: Projections
B28: =B27+1 -> 20 | C28: =C27+1 -> 2036 | D28: 300 | F28: =D28+E28 -> 300 | G28: =G27+F28 -> 4605.12 | I28: Projections
... B38: =B37+1 -> 30 | C38: =C37+1 -> 2046 | D38: 300 | F38: =D38+E38 -> 300 | G38: =G37+F38 -> 7605.12 | I38: Projections
B39: =B38+1 -> 31 | C39: =C38+1 -> 2047 | F39: =D39+E39 -> 0 | G39: =G38+F39 -> 7605.12 | I39: Projections
B40: =B39+1 -> 32 | C40: =C39+1 -> 2048 | F40: =D40+E40 -> 0 | G40: =G39+F40 -> 7605.12 | I40: Projections
B41: =B40+1 -> 33 | C41: =C40+1 -> 2049 | F41: =D41+E41 -> 0 | G41: =G40+F41 -> 7605.12 | I41: Projections
B42: =B41+1 -> 34 | C42: =C41+1 -> 2050 | F42: =D42+E42 -> 0 | G42: =G41+F42 -> 7605.12 | I42: Projections
B43: =B42+1 -> 35 | C43: =C42+1 -> 2051 | F43: =D43+E43 -> 0 | G43: =G42+F43 -> 7605.12 | I43: Projections
B44: =B43+1 -> 36 | C44: =C43+1 -> 2052 | F44: =D44+E44 -> 0 | G44: =G43+F44 -> 7605.12 | I44: Projections
B45: =B44+1 -> 37 | C45: =C44+1 -> 2053 | F45: =D45+E45 -> 0 | G45: =G44+F45 -> 7605.12 | I45: Projections
B46: =B45+1 -> 38 | C46: =C45+1 -> 2054 | F46: =D46+E46 -> 0 | G46: =G45+F46 -> 7605.12 | I46: Projections
B47: =B46+1 -> 39 | C47: =C46+1 -> 2055 | F47: =D47+E47 -> 0 | G47: =G46+F47 -> 7605.12 | I47: Projections
B48: =B47+1 -> 40 | C48: =C47+1 -> 2056 | F48: =D48+E48 -> 0 | G48: =G47+F48 -> 7605.12 | I48: Projections

Sheet NFC Growth model (MAI tables)
B2: EUC MODEL
B3: Stand volume (Column C) imported from MF output with suitable model according to Modified Buckspec approach (see accompanying document)
B4: Regime | C4: Carbon, planted at 2000 SPH, No thinning
B5: Species: | C5: E. grandis x urophylla
B6: Density: | C6: 0.487 | D6: To be specified for each species
C8: UTILIZABLE COMPONENTS | E8: BIOMASS COMPONENTS | M8: CARBON SEQUESTRATION
B9: Age | C9: Stand volume | D9: MAI | E9: Stem mass | F9: Bark | G9: Branches | H9: Leaves | I9: AGB | J9: Roots&stump | K9: Total biomass | L9: Carbon stocks | P9: CO2e
B10: (years) | C10: (m3 ha-1) | D10: (Mg ha-1 yr-1) | E10: (Mg ha-1) | F10: (Mg ha-1) | G10: (Mg ha-1) | H10: (Mg ha-1) | I10: (Mg ha-1) | J10: (Mg ha-1) | K10: (Mg ha-1) | L10: (Mg ha-1) | M10: MAI (Mg ha-1 yr-1) | N10: CAI (Mg ha-1) | O10: (Mg ha-1) | P10: MAI (Mg ha-1 yr-1) | Q10: CAI (Mg ha-1)
B11: 1 | C11: 0 | D11: =C11/B11 -> 0 | E11: =C11*$C$6 -> 0 | F11: =6.396-5.812/(1+0.008008*C11)+0.034011*C11 -> 0.584 | G11: 0 | H11: 0 | I11: =SUM(E11:H11) -> 0.584 | J11: =0.25*I11 -> 0.146 | K11: =SUM(I11)*1.25 -> 0.73 | L11: =K11*0.47 -> 0.3431 | M11: =L11/B11 -> 0.3431 | N11: =M11 -> 0.3431 | O11: =L11*3.667 -> 1.2581477 | P11: =O11/B11 -> 1.2581477 | Q11: 0
B12: 2 | C12: 19.19 | D12: =C12/B12 -> 9.595 | E12: =C12*$C$6 -> 9.34553 | F12: =6.396-5.812/(1+0.008008*C12)+0.034011*C12 -> 2.0108507 | G12: =EXP(0.19408*LN(C12)+1.510442) -> 8.0351838 | H12: =EXP(0.12038*LN(C12)+0.966132) -> 3.7500958 | I12: =SUM(E12:H12) -> 23.14166 | J12: =0.25*I12 -> 5.7854151 | K12: =SUM(I12)*1.25 -> 28.927075 | L12: =K12*0.47 -> 13.595725 | M12: =L12/B12 -> 6.7978627 | N12: =L12-L11 -> 13.252625 | O12: =L12*3.667 -> 49.855525 | P12: =O12/B12 -> 24.927763 | Q12: =O12-O11 -> 48.597377
B13: 3 | C13: 79.6 | D13: =C13/B13 -> 26.533333 | E13: =C13*$C$6 -> 38.7652 | F13: =6.396-5.812/(1+0.008008*C13)+0.034011*C13 -> 5.5538256 | G13: =EXP(0.19408*LN(C13)+1.510442) -> 10.590241 | H13: =EXP(0.12038*LN(C13)+0.966132) -> 4.4505913 | I13: =SUM(E13:H13) -> 59.359858 | J13: =0.25*I13 -> 14.839964 | K13: =SUM(I13)*1.25 -> 74.199822 | L13: =K13*0.47 -> 34.873916 | M13: =L13/B13 -> 11.624639 | N13: =L13-L12 -> 21.278191 | O13: =L13*3.667 -> 127.88265 | P13: =O13/B13 -> 42.62755 | Q13: =O13-O12 -> 78.027126
B14: 4 | C14: 138.58 | D14: =C14/B14 -> 34.645 | E14: =C14*$C$6 -> 67.48846 | F14: =6.396-5.812/(1+0.008008*C14)+0.034011*C14 -> 8.3544138 | G14: =EXP(0.19408*LN(C14)+1.510442) -> 11.793369 | H14: =EXP(0.12038*LN(C14)+0.966132) -> 4.7577729 | I14: =SUM(E14:H14) -> 92.394015 | J14: =0.25*I14 -> 23.098504 | K14: =SUM(I14)*1.25 -> 115.49252 | L14: =K14*0.47 -> 54.281484 | M14: =L14/B14 -> 13.570371 | N14: =L14-L13 -> 19.407568 | O14: =L14*3.667 -> 199.0502 | P14: =O14/B14 -> 49.76255 | Q14: =O14-O13 -> 71.16755
B15: 5 | C15: 195.5 | D15: =C15/B15 -> 39.1 | E15: =C15*$C$6 -> 95.2085 | F15: =6.396-5.812/(1+0.008008*C15)+0.034011*C15 -> 10.779762 | G15: =EXP(0.19408*LN(C15)+1.510442) -> 12.607889 | H15: =EXP(0.12038*LN(C15)+0.966132) -> 4.9589993 | I15: =SUM(E15:H15) -> 123.55515 | J15: =0.25*I15 -> 30.888788 | K15: =SUM(I15)*1.25 -> 154.44394 | L15: =K15*0.47 -> 72.588651 | M15: =L15/B15 -> 14.51773 | N15: =L15-L14 -> 18.307167 | O15: =L15*3.667 -> 266.18258 | P15: =O15/B15 -> 53.236517 | Q15: =O15-O14 -> 67.132381
B16: 6 | C16: 249.93 | D16: =C16/B16 -> 41.655 | E16: =C16*$C$6 -> 121.71591 | F16: =6.396-5.812/(1+0.008008*C16)+0.034011*C16 -> 12.959965 | G16: =EXP(0.19408*LN(C16)+1.510442) -> 13.223463 | H16: =EXP(0.12038*LN(C16)+0.966132) -> 5.1078152 | I16: =SUM(E16:H16) -> 153.00715 | J16: =0.25*I16 -> 38.251788 | K16: =SUM(I16)*1.25 -> 191.25894 | L16: =K16*0.47 -> 89.891703 | M16: =L16/B16 -> 14.98195 | N16: =L16-L15 -> 17.303052 | O16: =L16*3.667 -> 329.63287 | P16: =O16/B16 -> 54.938812 | Q16: =O16-O15 -> 63.450291
B17: 7 | C17: 301.81 | D17: =C17/B17 -> 43.115714 | E17: =C17*$C$6 -> 146.98147 | F17: =6.396-5.812/(1+0.008008*C17)+0.034011*C17 -> 14.9599 | G17: =EXP(0.19408*LN(C17)+1.510442) -> 13.716501 | H17: =EXP(0.12038*LN(C17)+0.966132) -> 5.2251183 | I17: =SUM(E17:H17) -> 180.88299 | J17: =0.25*I17 -> 45.220747 | K17: =SUM(I17)*1.25 -> 226.10374 | L17: =K17*0.47 -> 106.26876 | M17: =L17/B17 -> 15.181251 | N17: =L17-L16 -> 16.377053 | O17: =L17*3.667 -> 389.68753 | P17: =O17/B17 -> 55.669647 | Q17: =O17-O16 -> 60.054655
B18: 8 | C18: 351.15 | D18: =C18/B18 -> 43.89375 | E18: =C18*$C$6 -> 171.01005 | F18: =6.396-5.812/(1+0.008008*C18)+0.034011*C18 -> 16.814307 | G18: =EXP(0.19408*LN(C18)+1.510442) -> 14.125566 | H18: =EXP(0.12038*LN(C18)+0.966132) -> 5.3212321 | I18: =SUM(E18:H18) -> 207.27115 | J18: =0.25*I18 -> 51.817789 | K18: =SUM(I18)*1.25 -> 259.08894 | L18: =K18*0.47 -> 121.7718 | M18: =L18/B18 -> 15.221475 | N18: =L18-L17 -> 15.503047 | O18: =L18*3.667 -> 446.5372 | P18: =O18/B18 -> 55.81715 | Q18: =O18-O17 -> 56.849675
B19: 9 | C19: 397.56 | D19: =C19/B19 -> 44.173333 | E19: =C19*$C$6 -> 193.61172 | F19: =6.396-5.812/(1+0.008008*C19)+0.034011*C19 -> 18.528199 | G19: =EXP(0.19408*LN(C19)+1.510442) -> 14.470006 | H19: =EXP(0.12038*LN(C19)+0.966132) -> 5.4013447 | I19: =SUM(E19:H19) -> 232.01127 | J19: =0.25*I19 -> 58.002817 | K19: =SUM(I19)*1.25 -> 290.01409 | L19: =K19*0.47 -> 136.30662 | M19: =L19/B19 -> 15.14518 | N19: =L19-L18 -> 14.534817 | O19: =L19*3.667 -> 499.83638 | P19: =O19/B19 -> 55.537375 | Q19: =O19-O18 -> 53.299175
B20: 10 | C20: 441.36 | D20: =C20/B20 -> 44.136 | E20: =C20*$C$6 -> 214.94232 | F20: =6.396-5.812/(1+0.008008*C20)+0.034011*C20 -> 20.125341 | G20: =EXP(0.19408*LN(C20)+1.510442) -> 14.766516 | H20: =EXP(0.12038*LN(C20)+0.966132) -> 5.4697311 | I20: =SUM(E20:H20) -> 255.30391 | J20: =0.25*I20 -> 63.825977 | K20: =SUM(I20)*1.25 -> 319.12989 | L20: =K20*0.47 -> 149.99105 | M20: =L20/B20 -> 14.999105 | N20: =L20-L19 -> 13.684425 | O20: =L20*3.667 -> 550.01717 | P20: =O20/B20 -> 55.001717 | Q20: =O20-O19 -> 50.180787
B21: 11 | C21: 482.68 | D21: =C21/B21 -> 43.88 | E21: =C21*$C$6 -> 235.06516 | F21: =6.396-5.812/(1+0.008008*C21)+0.034011*C21 -> 21.617848 | G21: =EXP(0.19408*LN(C21)+1.510442) -> 15.025233 | H21: =EXP(0.12038*LN(C21)+0.966132) -> 5.528976 | I21: =SUM(E21:H21) -> 277.23722 | J21: =0.25*I21 -> 69.309304 | K21: =SUM(I21)*1.25 -> 346.54652 | L21: =K21*0.47 -> 162.87687 | M21: =L21/B21 -> 14.806988 | N21: =L21-L20 -> 12.885819 | O21: =L21*3.667 -> 597.26946 | P21: =O21/B21 -> 54.297224 | Q21: =O21-O20 -> 47.252298
B22: 12 | C22: 520.9 | D22: =C22/B22 -> 43.408333 | E22: =C22*$C$6 -> 253.6783 | F22: =6.396-5.812/(1+0.008008*C22)+0.034011*C22 -> 22.988449 | G22: =EXP(0.19408*LN(C22)+1.510442) -> 15.249103 | H22: =EXP(0.12038*LN(C22)+0.966132) -> 5.5799292 | I22: =SUM(E22:H22) -> 297.49578 | J22: =0.25*I22 -> 74.373945 | K22: =SUM(I22)*1.25 -> 371.86973 | L22: =K22*0.47 -> 174.77877 | M22: =L22/B22 -> 14.564898 | N22: =L22-L21 -> 11.901907 | O22: =L22*3.667 -> 640.91376 | P22: =O22/B22 -> 53.40948 | Q22: =O22-O21 -> 43.644292
B23: 13 | C23: 557.7 | D23: =C23/B23 -> 42.9 | E23: =C23*$C$6 -> 271.5999 | F23: =6.396-5.812/(1+0.008008*C23)+0.034011*C23 -> 24.300646 | G23: =EXP(0.19408*LN(C23)+1.510442) -> 15.452475 | H23: =EXP(0.12038*LN(C23)+0.966132) -> 5.6259712 | I23: =SUM(E23:H23) -> 316.97899 | J23: =0.25*I23 -> 79.244748 | K23: =SUM(I23)*1.25 -> 396.22374 | L23: =K23*0.47 -> 186.22516 | M23: =L23/B23 -> 14.325012 | N23: =L23-L22 -> 11.446387 | O23: =L23*3.667 -> 682.88766 | P23: =O23/B23 -> 52.52982 | Q23: =O23-O22 -> 41.9739
... B30: 20 | C30: 745.56 | D30: =C30/B30 -> 37.278 | E30: =C30*$C$6 -> 363.08772 | F30: =6.396-5.812/(1+0.008008*C30)+0.034011*C30 -> 30.919435 | G30: =EXP(0.19408*LN(C30)+1.510442) -> 16.348129 | H30: =EXP(0.12038*LN(C30)+0.966132) -> 5.826064 | I30: =SUM(E30:H30) -> 416.18135 | J30: =0.25*I30 -> 104.04534 | K30: =SUM(I30)*1.25 -> 520.22668 | L30: =K30*0.47 -> 244.50654 | M30: =L30/B30 -> 12.225327 | N30: =L30-L29 -> 6.0154524 | O30: =L30*3.667 -> 896.60549 | P30: =O30/B30 -> 44.830274 | Q30: =O30-O29 -> 22.058664
B32: PINE MODEL
B33: Stand volume (Column C) imported from MF output with suitable model according to Modified Buckspec approach (see accompanying document)
B34: Regime | C34: Sawlog regime, planted at 1111 PH thinned to 600 SPH at 8 years of age
B35: Species: | C35: Pinus caribaea
B36: Density: | C36: 0.412 | D36: To be specified for each species
C38: UTILIZABLE COMPONENTS | E38: BIOMASS COMPONENTS | M38: CARBON SEQUESTRATION
B39: Age | C39: Stand volume | D39: MAI | E39: Stem mass | F39: Bark | G39: Branches | H39: Leaves | I39: AGB | J39: Roots&stump | K39: Total biomass | L39: Carbon stocks | N39: CAIC | O39: CO2 sequested
B40: (years) | C40: (m3 ha-1) | D40: (Mg ha-1 yr-1) | E40: (Mg ha-1) | F40: (Mg ha-1) | G40: (Mg ha-1) | H40: (Mg ha-1) | I40: (Mg ha-1) | J40: (Mg ha-1) | K40: (Mg ha-1) | L40: (Mg ha-1) | M40: (Mg ha-1 yr-1) | N40: (Mg ha-1) | O40: (Mg ha-1) | P40: (Mg ha-1 yr-1)
B41: 1 | C41: 0 | D41: =C41/B41 -> 0 | E41: =$C$36*C41 -> 0 | F41: =97.81+(-96.6-3.95*B41)/(1+0.0422*B41+0.00001843*B41^2) -> 1.3331031 | G41: =EXP(0.24475*LN(B41)+0.000612*B41+1.714245) -> 5.555881 | H41: =EXP(0.0551341*LN(G41)-0.00017*G41+2.136863) -> 9.3041971 | I41: =SUM(E41:H41) -> 16.193181 | J41: =0.2*I41 -> 3.2386362 | K41: =SUM(I41)*1.25 -> 20.241476 | L41: =K41*0.47 -> 9.5134939 | M41: =L41/B41 -> 9.5134939 | N41: =M41 -> 9.5134939 | O41: =L41*3.667 -> 34.885982 | P41: =O41/B41 -> 34.885982
B42: 2 | C42: 0 | D42: =C42/B42 -> 0 | E42: =$C$36*C42 -> 0 | F42: =97.81+(-96.6-3.95*B42)/(1+0.0422*B42+0.00001843*B42^2) -> 1.4498964 | G42: =EXP(0.24475*LN(B42)+0.000612*B42+1.714245) -> 6.5871236 | H42: =EXP(0.0551341*LN(G42)-0.00017*G42+2.136863) -> 9.3903015 | I42: =SUM(E42:H42) -> 17.427322 | J42: =0.2*I42 -> 3.4854643 | K42: =SUM(I42)*1.25 -> 21.784152 | L42: =K42*0.47 -> 10.238551 | M42: =L42/B42 -> 5.1192757 | N42: =L42-L41 -> 0.72505747 | O42: =L42*3.667 -> 37.544768 | P42: =O42/B42 -> 18.772384
B43: 3 | C43: 8.42 | D43: =C43/B43 -> 2.8066667 | E43: =$C$36*C43 -> 3.46904 | F43: =97.81+(-96.6-3.95*B43)/(1+0.0422*B43+0.00001843*B43^2) -> 1.5610783 | G43: =EXP(0.24475*LN(B43)+0.000612*B43+1.714245) -> 7.2788025 | H43: =EXP(0.0551341*LN(G43)-0.00017*G43+2.136863) -> 9.4410286 | I43: =SUM(E43:H43) -> 21.749949 | J43: =0.2*I43 -> 4.3499899 | K43: =SUM(I43)*1.25 -> 27.187437 | L43: =K43*0.47 -> 12.778095 | M43: =L43/B43 -> 4.2593651 | N43: =L43-L42 -> 2.5395439 | O43: =L43*3.667 -> 46.857275 | P43: =O43/B43 -> 15.619092
B44: 4 | C44: 25.62 | D44: =C44/B44 -> 6.405 | E44: =$C$36*C44 -> 10.55544 | F44: =97.81+(-96.6-3.95*B44)/(1+0.0422*B44+0.00001843*B44^2) -> 1.6672472 | G44: =EXP(0.24475*LN(B44)+0.000612*B44+1.714245) -> 7.8145591 | H44: =EXP(0.0551341*LN(G44)-0.00017*G44+2.136863) -> 9.4772065 | I44: =SUM(E44:H44) -> 29.514453 | J44: =0.2*I44 -> 5.9028906 | K44: =SUM(I44)*1.25 -> 36.893066 | L44: =K44*0.47 -> 17.339741 | M44: =L44/B44 -> 4.3349353 | N44: =L44-L43 -> 4.5616458 | O44: =L44*3.667 -> 63.58483 | P44: =O44/B44 -> 15.896208
B45: 5 | C45: 52.11 | D45: =C45/B45 -> 10.422 | E45: =$C$36*C45 -> 21.46932 | F45: =97.81+(-96.6-3.95*B45)/(1+0.0422*B45+0.00001843*B45^2) -> 1.768919 | G45: =EXP(0.24475*LN(B45)+0.000612*B45+1.714245) -> 8.2582684 | H45: =EXP(0.0551341*LN(G45)-0.00017*G45+2.136863) -> 9.5053902 | I45: =SUM(E45:H45) -> 41.001898 | J45: =0.2*I45 -> 8.2003795 | K45: =SUM(I45)*1.25 -> 51.252372 | L45: =K45*0.47 -> 24.088615 | M45: =L45/B45 -> 4.817723 | N45: =L45-L44 -> 6.7488738 | O45: =L45*3.667 -> 88.332951 | P45: =O45/B45 -> 17.66659
B46: 6 | C46: 87.21 | D46: =C46/B46 -> 14.535 | E46: =$C$36*C46 -> 35.93052 | F46: =97.81+(-96.6-3.95*B46)/(1+0.0422*B46+0.00001843*B46^2) -> 1.8665405 | G46: =EXP(0.24475*LN(B46)+0.000612*B46+1.714245) -> 8.6404108 | H46: =EXP(0.0551341*LN(G46)-0.00017*G46+2.136863) -> 9.5285072 | I46: =SUM(E46:H46) -> 55.965979 | J46: =0.2*I46 -> 11.193196 | K46: =SUM(I46)*1.25 -> 69.957473 | L46: =K46*0.47 -> 32.880012 | M46: =L46/B46 -> 5.4800021 | N46: =L46-L45 -> 8.7913975 | O46: =L46*3.667 -> 120.57101 | P46: =O46/B46 -> 20.095168
B47: 7 | C47: 129.48 | D47: =C47/B47 -> 18.497143 | E47: =$C$36*C47 -> 53.34576 | F47: =97.81+(-96.6-3.95*B47)/(1+0.0422*B47+0.00001843*B47^2) -> 1.9605009 | G47: =EXP(0.24475*LN(B47)+0.000612*B47+1.714245) -> 8.97812 | H47: =EXP(0.0551341*LN(G47)-0.00017*G47+2.136863) -> 9.5481223 | I47: =SUM(E47:H47) -> 73.832503 | J47: =0.2*I47 -> 14.766501 | K47: =SUM(I47)*1.25 -> 92.290629 | L47: =K47*0.47 -> 43.376596 | M47: =L47/B47 -> 6.1966565 | N47: =L47-L46 -> 10.496583 | O47: =L47*3.667 -> 159.06198 | P47: =O47/B47 -> 22.723139
B48: 8 | C48: 24.29 | D48: =C48/B48 -> 3.03625 | E48: =$C$36*C48 -> 10.00748 | F48: =97.81+(-96.6-3.95*B48)/(1+0.0422*B48+0.00001843*B48^2) -> 2.0511405 | G48: =EXP(0.24475*LN(B48)+0.000612*B48+1.714245) -> 9.2820675 | H48: =EXP(0.0551341*LN(G48)-0.00017*G48+2.136863) -> 9.5651709 | I48: =SUM(E48:H48) -> 30.905859 | J48: =0.2*I48 -> 6.1811718 | K48: =SUM(I48)*1.25 -> 38.632324 | L48: =K48*0.47 -> 18.157192 | M48: =L48/B48 -> 2.269649 | N48: =L48-L47 -> -25.219404 | O48: =L48*3.667 -> 66.582424 | P48: =O48/B48 -> 8.3228029
B49: 9 | C49: 123.48 | D49: =C49/B49 -> 13.72 | E49: =$C$36*C49 -> 50.87376 | F49: =97.81+(-96.6-3.95*B49)/(1+0.0422*B49+0.00001843*B49^2) -> 2.1387584 | G49: =EXP(0.24475*LN(B49)+0.000612*B49+1.714245) -> 9.5593881 | H49: =EXP(0.0551341*LN(G49)-0.00017*G49+2.136863) -> 9.5802572 | I49: =SUM(E49:H49) -> 72.152164 | J49: =0.2*I49 -> 14.430433 | K49: =SUM(I49)*1.25 -> 90.190205 | L49: =K49*0.47 -> 42.389396 | M49: =L49/B49 -> 4.7099329 | N49: =L49-L48 -> 24.232204 | O49: =L49*3.667 -> 155.44192 | P49: =O49/B49 -> 17.271324
B50: 10 | C50: 162.69 | D50: =C50/B50 -> 16.269 | E50: =$C$36*C50 -> 67.02828 | F50: =97.81+(-96.6-3.95*B50)/(1+0.0422*B50+0.00001843*B50^2) -> 2.2236186 | G50: =EXP(0.24475*LN(B50)+0.000612*B50+1.714245) -> 9.8151067 | H50: =EXP(0.0551341*LN(G50)-0.00017*G50+2.136863) -> 9.5937942 | I50: =SUM(E50:H50) -> 88.6608 | J50: =0.2*I50 -> 17.73216 | K50: =SUM(I50)*1.25 -> 110.826 | L50: =K50*0.47 -> 52.08822 | M50: =L50/B50 -> 5.208822 | N50: =L50-L49 -> 9.6988236 | O50: =L50*3.667 -> 191.0075 | P50: =O50/B50 -> 19.10075
...

Sheet Outgrower Woody C Pool
A1: New Forests: Outgrower Area Afforestation and Carbon Stock Tables
A3: Eucalyptus
B4: Hectares | AD4: Carbon Stock in tC
B6: Year | C6: 0-1 | D6: 1-2 | E6: 2-3 | F6: 3-4 | G6: 4-5 | H6: 5-6 | I6: 6-7 | J6: 7-8 | K6: 8-9 | L6: 9-10 | M6: 10-11 | N6: 11-12 | O6: 12-13 | P6: 13-14 | Q6: 14-15 | R6: 15-16 | S6: 16-17 | T6: 17-18 | U6: 18-19 | V6: 19-20 | W6: 20-21 | X6: 21-22 | Y6: 22-23 | Z6: 23-24 | AA6: 24-25 | AB6: TOTAL | AD6: Year | AE6: 0-1 | AF6: 1-2 | AG6: 2-3 | AH6: 3-4 | AI6: 4-5 | AJ6: 5-6 | AK6: 6-7 | AL6: 7-8 | AM6: 8-9 | AN6: 9-10 | AO6: 10-11 | AP6: 11-12 | AQ6: 12-13 | AR6: 13-14 | AS6: 14-15 | AT6: 15-16 | AU6: 16-17 | AV6: 17-18 | AW6: 18-19 | AX6: 19-20 | AY6: 20-21 | AZ6: 21-22 | BA6: 22-23 | BB6: 23-24 | BC6: 24-25 | BD6: TOTAL
B7: =B8-1 -> 2017 | C7: ='Project area'!D9 -> 267.16 | AB7: =SUM(C7:W7) -> 267.16 | AD7: =AD8-1 -> 2017 | AE7: =C7*AE$37 -> 80.148 | AF7: =D7*AF$37 -> 0 | AG7: =E7*AG$37 -> 0 | AH7: =F7*AH$37 -> 0 | AI7: =G7*AI$37 -> 0 | AJ7: =H7*AJ$37 -> 0 | AK7: =I7*AK$37 -> 0 | AL7: =J7*AL$37 -> 0 | ... BC7: =AA7*BC$37 -> 0 | BD7: =SUM(AE7:BC7) -> 80.148
B8: =B9-1 -> 2018 | C8: ='Project area'!D10 -> 100.9 | D8: =C7 -> 267.16 | AB8: =SUM(C8:W8) -> 368.06 | AD8: =AD9-1 -> 2018 | AE8: =C8*AE$37 -> 30.27 | AF8: =D8*AF$37 -> 3632.234 | AG8: =E8*AG$37 -> 0 | AH8: =F8*AH$37 -> 0 | AI8: =G8*AI$37 -> 0 | AJ8: =H8*AJ$37 -> 0 | AK8: =I8*AK$37 -> 0 | AL8: =J8*AL$37 -> 0 | ... BC8: =AA8*BC$37 -> 0 | BD8: =SUM(AE8:BC8) -> 3662.504
B9: =B10-1 -> 2019 | C9: ='Project area'!D11 -> 243.04 | D9: =C8 -> 100.9 | E9: =C7 -> 267.16 | AB9: =SUM(C9:W9) -> 611.1 | AD9: =AD10-1 -> 2019 | AE9: =C9*AE$37 -> 72.912 | AF9: =D9*AF$37 -> 1371.8087 | AG9: =E9*AG$37 -> 9316.9155 | AH9: =F9*AH$37 -> 0 | AI9: =G9*AI$37 -> 0 | AJ9: =H9*AJ$37 -> 0 | AK9: =I9*AK$37 -> 0 | AL9: =J9*AL$37 -> 0 | ... BC9: =AA9*BC$37 -> 0 | BD9: =SUM(AE9:BC9) -> 10761.636
B10: =B11-1 -> 2020 | C10: ='Project area'!D12 -> 69.32 | D10: =C9 -> 243.04 | E10: =C8 -> 100.9 | F10: =C7 -> 267.16 | AB10: =SUM(C10:W10) -> 680.42 | AD10: =AD11-1 -> 2020 | AE10: =C10*AE$37 -> 20.796 | AF10: =D10*AF$37 -> 3304.3051 | AG10: =E10*AG$37 -> 3518.7782 | AH10: =F10*AH$37 -> 14501.841 | AI10: =G10*AI$37 -> 0 | AJ10: =H10*AJ$37 -> 0 | AK10: =I10*AK$37 -> 0 | AL10: =J10*AL$37 -> 0 | ... BC10: =AA10*BC$37 -> 0 | BD10: =SUM(AE10:BC10) -> 21345.721
B11: 2021 | C11: ='Project area'!D13 -> 142.3 | D11: =C10 -> 69.32 | E11: =C9 -> 243.04 | F11: =C8 -> 100.9 | G11: =C7 -> 267.16 | AB11: =SUM(C11:W11) -> 822.72 | AD11: 2021 | AE11: =C11*AE$37 -> 42.69 | AF11: =D11*AF$37 -> 942.45569 | AG11: =E11*AG$37 -> 8475.7566 | AH11: =F11*AH$37 -> 5477.0017 | AI11: =G11*AI$37 -> 19392.784 | AJ11: =H11*AJ$37 -> 0 | AK11: =I11*AK$37 -> 0 | AL11: =J11*AL$37 -> 0 | ... BC11: =AA11*BC$37 -> 0 | BD11: =SUM(AE11:BC11) -> 34330.688
B12: =B11+1 -> 2022 | C12: ='Project area'!D14 -> 35.19 | D12: =C11 -> 142.3 | E12: =C10 -> 69.32 | F12: =C9 -> 243.04 | G12: =C8 -> 100.9 | H12: =C7 -> 267.16 | AB12: =SUM(C12:W12) -> 857.91 | AD12: =AD11+1 -> 2022 | AE12: =C12*AE$37 -> 10.557 | AF12: =D12*AF$37 -> 1934.6717 | AG12: =E12*AG$37 -> 2417.4599 | AH12: =F12*AH$37 -> 13192.572 | AI12: =G12*AI$37 -> 7324.1949 | AJ12: =H12*AJ$37 -> 24015.467 | AK12: =I12*AK$37 -> 0 | AL12: =J12*AL$37 -> 0 | ... BC12: =AA12*BC$37 -> 0 | BD12: =SUM(AE12:BC12) -> 48894.923
B13: =B12+1 -> 2023 | C13: ='Project area'!D15 -> 95.61 | D13: =C12 -> 35.19 | E13: =C11 -> 142.3 | F13: =C10 -> 69.32 | G13: =C9 -> 243.04 | H13: =C8 -> 100.9 | I13: =C7 -> 267.16 | AB13: =SUM(C13:W13) -> 953.52 | AD13: =AD12+1 -> 2023 | AE13: =C13*AE$37 -> 28.683 | AF13: =D13*AF$37 -> 478.43358 | AG13: =E13*AG$37 -> 4962.5583 | AH13: =F13*AH$37 -> 3762.7925 | AI13: =G13*AI$37 -> 17641.946 | AJ13: =H13*AJ$37 -> 9070.0728 | AK13: =I13*AK$37 -> 28390.761 | AL13: =J13*AL$37 -> 0 | ... BC13: =AA13*BC$37 -> 0 | BD13: =SUM(AE13:BC13) -> 64335.247
B14: =B13+1 -> 2024 | C14: ='Project area'!D16 -> 36.41 | D14: =C13 -> 95.61 | E14: =C12 -> 35.19 | F14: =C11 -> 142.3 | G14: =C10 -> 69.32 | H14: =C9 -> 243.04 | I14: =C8 -> 100.9 | J14: =C7 -> 267.16 | AB14: =SUM(C14:W14) -> 989.93 | AD14: =AD13+1 -> 2024 | AE14: =C14*AE$37 -> 10.923 | AF14: =D14*AF$37 -> 1299.8873 | AG14: =E14*AG$37 -> 1227.2131 | AH14: =F14*AH$37 -> 7724.2552 | AI14: =G14*AI$37 -> 5031.8453 | AJ14: =H14*AJ$37 -> 21847.279 | AK14: =I14*AK$37 -> 10722.517 | AL14: =J14*AL$37 -> 32532.555 | ... BC14: =AA14*BC$37 -> 0 | BD14: =SUM(AE14:BC14) -> 80396.476
B15: =B14+1 -> 2025 | C15: ='Project area'!D17 -> 62.52 | D15: =C14 -> 36.41 | E15: =C13 -> 95.61 | F15: =C12 -> 35.19 | G15: =C11 -> 142.3 | H15: =C10 -> 69.32 | I15: =C9 -> 243.04 | J15: =C8 -> 100.9 | K15: =C7 -> 267.16 | AB15: =SUM(C15:W15) -> 1052.45 | AD15: =AD14+1 -> 2025 | AE15: =C15*AE$37 -> 18.756 | AF15: =D15*AF$37 -> 495.02036 | AG15: =E15*AG$37 -> 3334.2951 | AH15: =F15*AH$37 -> 1910.1654 | AI15: =G15*AI$37 -> 10329.365 | AJ15: =H15*AJ$37 -> 6231.2928 | AK15: =I15*AK$37 -> 25827.558 | AL15: =J15*AL$37 -> 12286.775 | ... BC15: =AA15*BC$37 -> 0 | BD15: =SUM(AE15:BC15) -> 60513.376
B16: =B15+1 -> 2026 | C16: ='Project area'!D18 -> 300 | D16: =C15 -> 62.52 | E16: =C14 -> 36.41 | F16: =C13 -> 95.61 | G16: =C12 -> 35.19 | H16: =C11 -> 142.3 | I16: =C10 -> 69.32 | J16: =C9 -> 243.04 | K16: =C8 -> 100.9 | L16: =C7 -> 267.16 | AB16: =SUM(C16:W16) -> 1352.45 | AD16: =AD15+1 -> 2026 | AE16: =C16*AE$37 -> 90 | AF16: =D16*AF$37 -> 850.00475 | AG16: =E16*AG$37 -> 1269.7593 | AH16: =F16*AH$37 -> 5189.8527 | AI16: =G16*AI$37 -> 2554.3946 | AJ16: =H16*AJ$37 -> 12791.589 | AK16: =I16*AK$37 -> 7366.5502 | AL16: =J16*AL$37 -> 29595.419 | ... BC16: =AA16*BC$37 -> 0 | BD16: =SUM(AE16:BC16) -> 63370.074
B17: =B16+1 -> 2027 | C17: ='Project area'!D19 -> 300 | D17: =C16 -> 300 | E17: =C15 -> 62.52 | F17: =C14 -> 36.41 | G17: =C13 -> 95.61 | H17: =C12 -> 35.19 | I17: =C11 -> 142.3 | J17: =C10 -> 69.32 | K17: =C9 -> 243.04 | L17: =C8 -> 100.9 | M17: =C7 -> 267.16 | AB17: =SUM(C17:W17) -> 1652.45 | AD17: =AD16+1 -> 2027 | AE17: =C17*AE$37 -> 90 | AF17: =D17*AF$37 -> 4078.7176 | AG17: =E17*AG$37 -> 2180.3173 | AH17: =F17*AH$37 -> 1976.3888 | AI17: =G17*AI$37 -> 6940.2009 | AJ17: =H17*AJ$37 -> 3163.289 | AK17: =I17*AK$37 -> 15122.044 | AL17: =J17*AL$37 -> 8441.2214 | ... BC17: =AA17*BC$37 -> 0 | BD17: =SUM(AE17:BC17) -> 52753.815
B18: =B17+1 -> 2028 | C18: ='Project area'!D20 -> 300 | D18: =C17 -> 300 | E18: =C16 -> 300 | F18: =C15 -> 62.52 | G18: =C14 -> 36.41 | H18: =C13 -> 95.61 | I18: =C12 -> 35.19 | J18: =C11 -> 142.3 | K18: =C10 -> 69.32 | L18: =C9 -> 243.04 | M18: =C8 -> 100.9 | N18: =C7 -> 267.16 | AB18: =SUM(C18:W18) -> 1952.45 | AD18: =AD17+1 -> 2028 | AE18: =C18*AE$37 -> 90 | AF18: =D18*AF$37 -> 4078.7176 | AG18: =E18*AG$37 -> 10462.175 | AH18: =F18*AH$37 -> 3393.6784 | AI18: =G18*AI$37 -> 2642.9528 | AJ18: =H18*AJ$37 -> 8594.5457 | AK18: =I18*AK$37 -> 3739.5975 | AL18: =J18*AL$37 -> 17328.128 | ... BC18: =AA18*BC$37 -> 0 | BD18: =SUM(AE18:BC18) -> 71675.515
B19: =B18+1 -> 2029 | C19: ='Project area'!D21 -> 300 | D19: =C18 -> 300 | E19: =C17 -> 300 | F19: =C16 -> 300 | G19: =C15 -> 62.52 | H19: =C14 -> 36.41 | I19: =C13 -> 95.61 | J19: =C12 -> 35.19 | K19: =C11 -> 142.3 | L19: =C10 -> 69.32 | M19: =C9 -> 243.04 | N19: =C8 -> 100.9 | O19: =C7 -> 267.16 | AB19: =SUM(C19:W19) -> 2252.45 | AD19: =AD18+1 -> 2029 | AE19: =C19*AE$37 -> 90 | AF19: =D19*AF$37 -> 4078.7176 | AG19: =E19*AG$37 -> 10462.175 | AH19: =F19*AH$37 -> 16284.445 | AI19: =G19*AI$37 -> 4538.2424 | AJ19: =H19*AJ$37 -> 3272.9569 | AK19: =I19*AK$37 -> 10160.356 | AL19: =J19*AL$37 -> 4285.1498 | ... BC19: =AA19*BC$37 -> 0 | BD19: =SUM(AE19:BC19) -> 87502.731
B20: =B19+1 -> 2030 | C20: ='Project area'!D22 -> 300 | D20: =C19 -> 300 | E20: =C18 -> 300 | F20: =C17 -> 300 | G20: =C16 -> 300 | H20: =C15 -> 62.52 | I20: =C14 -> 36.41 | J20: =C13 -> 95.61 | K20: =C12 -> 35.19 | L20: =C11 -> 142.3 | M20: =C10 -> 69.32 | N20: =C9 -> 243.04 | O20: =C8 -> 100.9 | P20: =C7 -> 267.16 | AB20: =SUM(C20:W20) -> 2552.45 | AD20: =AD19+1 -> 2030 | AE20: =C20*AE$37 -> 90 | AF20: =D20*AF$37 -> 4078.7176 | AG20: =E20*AG$37 -> 10462.175 | AH20: =F20*AH$37 -> 16284.445 | AI20: =G20*AI$37 -> 21776.595 | AJ20: =H20*AJ$37 -> 5620.0293 | AK20: =I20*AK$37 -> 3869.2454 | AL20: =J20*AL$37 -> 11642.602 | ... BC20: =AA20*BC$37 -> 0 | BD20: =SUM(AE20:BC20) -> 122718.73
B21: =B20+1 -> 2031 | C21: ='Project area'!D23 -> 300 | D21: =C20 -> 300 | E21: =C19 -> 300 | F21: =C18 -> 300 | G21: =C17 -> 300 | H21: =C16 -> 300 | I21: =C15 -> 62.52 | J21: =C14 -> 36.41 | K21: =C13 -> 95.61 | L21: =C12 -> 35.19 | M21: =C11 -> 142.3 | N21: =C10 -> 69.32 | O21: =C9 -> 243.04 | P21: =C8 -> 100.9 | Q21: =C7 -> 267.16 | AB21: =SUM(C21:W21) -> 2852.45 | AD21: =AD20+1 -> 2031 | AE21: =C21*AE$37 -> 90 | AF21: =D21*AF$37 -> 4078.7176 | AG21: =E21*AG$37 -> 10462.175 | AH21: =F21*AH$37 -> 16284.445 | AI21: =G21*AI$37 -> 21776.595 | AJ21: =H21*AJ$37 -> 26967.511 | AK21: =I21*AK$37 -> 6643.9226 | AL21: =J21*AL$37 -> 4433.7114 | ... BC21: =AA21*BC$37 -> 0 | BD21: =SUM(AE21:BC21) -> 155072.32
B22: =B21+1 -> 2032 | C22: ='Project area'!D24 -> 300 | D22: =C21 -> 300 | E22: =C20 -> 300 | F22: =C19 -> 300 | G22: =C18 -> 300 | H22: =C17 -> 300 | I22: =C16 -> 300 | J22: =C15 -> 62.52 | K22: =C14 -> 36.41 | L22: =C13 -> 95.61 | M22: =C12 -> 35.19 | N22: =C11 -> 142.3 | O22: =C10 -> 69.32 | P22: =C9 -> 243.04 | Q22: =C8 -> 100.9 | R22: =C7 -> 267.16 | AB22: =SUM(C22:W22) -> 3152.45 | AD22: =AD21+1 -> 2032 | AE22: =C22*AE$37 -> 90 | AF22: =D22*AF$37 -> 4078.7176 | AG22: =E22*AG$37 -> 10462.175 | AH22: =F22*AH$37 -> 16284.445 | AI22: =G22*AI$37 -> 21776.595 | AJ22: =H22*AJ$37 -> 26967.511 | AK22: =I22*AK$37 -> 31880.627 | AL22: =J22*AL$37 -> 7613.1732 | ... BC22: =AA22*BC$37 -> 0 | BD22: =SUM(AE22:BC22) -> 199549.72
B23: =B22+1 -> 2033 | C23: ='Project area'!D25 -> 300 | D23: =C22 -> 300 | E23: =C21 -> 300 | F23: =C20 -> 300 | G23: =C19 -> 300 | H23: =C18 -> 300 | I23: =C17 -> 300 | J23: =C16 -> 300 | K23: =C15 -> 62.52 | L23: =C14 -> 36.41 | M23: =C13 -> 95.61 | N23: =C12 -> 35.19 | O23: =C11 -> 142.3 | P23: =C10 -> 69.32 | Q23: =C9 -> 243.04 | R23: =C8 -> 100.9 | S23: =C7 -> 267.16 | AB23: =SUM(C23:W23) -> 3452.45 | AD23: =AD22+1 -> 2033 | AE23: =C23*AE$37 -> 90 | AF23: =D23*AF$37 -> 4078.7176 | AG23: =E23*AG$37 -> 10462.175 | AH23: =F23*AH$37 -> 16284.445 | AI23: =G23*AI$37 -> 21776.595 | AJ23: =H23*AJ$37 -> 26967.511 | AK23: =I23*AK$37 -> 31880.627 | AL23: =J23*AL$37 -> 36531.541 | ... BC23: =AA23*BC$37 -> 0 | BD23: =SUM(AE23:BC23) -> 208584.99
B24: =B23+1 -> 2034 | C24: ='Project area'!D26 -> 300 | D24: =C23 -> 300 | E24: =C22 -> 300 | F24: =C21 -> 300 | G24: =C20 -> 300 | H24: =C19 -> 300 | I24: =C18 -> 300 | J24: =C17 -> 300 | K24: =C16 -> 300 | L24: =C15 -> 62.52 | M24: =C14 -> 36.41 | N24: =C13 -> 95.61 | O24: =C12 -> 35.19 | P24: =C11 -> 142.3 | Q24: =C10 -> 69.32 | R24: =C9 -> 243.04 | S24: =C8 -> 100.9 | T24: =C7 -> 267.16 | AB24: =SUM(C24:W24) -> 3752.45 | AD24: =AD23+1 -> 2034 | AE24: =C24*AE$37 -> 90 | AF24: =D24*AF$37 -> 4078.7176 | AG24: =E24*AG$37 -> 10462.175 | AH24: =F24*AH$37 -> 16284.445 | AI24: =G24*AI$37 -> 21776.595 | AJ24: =H24*AJ$37 -> 26967.511 | AK24: =I24*AK$37 -> 31880.627 | AL24: =J24*AL$37 -> 36531.541 | ... BC24: =AA24*BC$37 -> 0 | BD24: =SUM(AE24:BC24) -> 211441.69
B25: =B24+1 -> 2035 | C25: ='Project area'!D27 -> 300 | D25: =C24 -> 300 | E25: =C23 -> 300 | F25: =C22 -> 300 | G25: =C21 -> 300 | H25: =C20 -> 300 | I25: =C19 -> 300 | J25: =C18 -> 300 | K25: =C17 -> 300 | L25: =C16 -> 300 | M25: =C15 -> 62.52 | N25: =C14 -> 36.41 | O25: =C13 -> 95.61 | P25: =C12 -> 35.19 | Q25: =C11 -> 142.3 | R25: =C10 -> 69.32 | S25: =C9 -> 243.04 | T25: =C8 -> 100.9 | U25: =C7 -> 267.16 | AB25: =SUM(C25:W25) -> 4052.45 | AD25: =AD24+1 -> 2035 | AE25: =C25*AE$37 -> 90 | AF25: =D25*AF$37 -> 4078.7176 | AG25: =E25*AG$37 -> 10462.175 | AH25: =F25*AH$37 -> 16284.445 | AI25: =G25*AI$37 -> 21776.595 | AJ25: =H25*AJ$37 -> 26967.511 | AK25: =I25*AK$37 -> 31880.627 | AL25: =J25*AL$37 -> 36531.541 | ... BC25: =AA25*BC$37 -> 0 | BD25: =SUM(AE25:BC25) -> 200825.43
B26: =B25+1 -> 2036 | C26: ='Project area'!D28 -> 300 | D26: =C25 -> 300 | E26: =C24 -> 300 | F26: =C23 -> 300 | G26: =C22 -> 300 | H26: =C21 -> 300 | I26: =C20 -> 300 | J26: =C19 -> 300 | K26: =C18 -> 300 | L26: =C17 -> 300 | M26: =C16 -> 300 | N26: =C15 -> 62.52 | O26: =C14 -> 36.41 | P26: =C13 -> 95.61 | Q26: =C12 -> 35.19 | R26: =C11 -> 142.3 | S26: =C10 -> 69.32 | T26: =C9 -> 243.04 | U26: =C8 -> 100.9 | V26: =C7 -> 267.16 | AB26: =SUM(C26:W26) -> 4352.45 | AD26: =AD25+1 -> 2036 | AE26: =C26*AE$37 -> 90 | AF26: =D26*AF$37 -> 4078.7176 | AG26: =E26*AG$37 -> 10462.175 | AH26: =F26*AH$37 -> 16284.445 | AI26: =G26*AI$37 -> 21776.595 | AJ26: =H26*AJ$37 -> 26967.511 | AK26: =I26*AK$37 -> 31880.627 | AL26: =J26*AL$37 -> 36531.541 | ... BC26: =AA26*BC$37 -> 0 | BD26: =SUM(AE26:BC26) -> 219747.13
B27: =B26+1 -> 2037 | C27: ='Project area'!D29 -> 300 | D27: =C26 -> 300 | E27: =C25 -> 300 | F27: =C24 -> 300 | G27: =C23 -> 300 | H27: =C22 -> 300 | I27: =C21 -> 300 | J27: =C20 -> 300 | K27: =C19 -> 300 | L27: =C18 -> 300 | M27: =C17 -> 300 | N27: =C16 -> 300 | O27: =C15 -> 62.52 | P27: =C14 -> 36.41 | Q27: =C13 -> 95.61 | R27: =C12 -> 35.19 | S27: =C11 -> 142.3 | T27: =C10 -> 69.32 | U27: =C9 -> 243.04 | V27: =C8 -> 100.9 | W27: =C7 -> 267.16 | AB27: =SUM(C27:W27) -> 4652.45 | AD27: =AD26+1 -> 2037 | AE27: =C27*AE$37 -> 90 | AF27: =D27*AF$37 -> 4078.7176 | AG27: =E27*AG$37 -> 10462.175 | AH27: =F27*AH$37 -> 16284.445 | AI27: =G27*AI$37 -> 21776.595 | AJ27: =H27*AJ$37 -> 26967.511 | AK27: =I27*AK$37 -> 31880.627 | AL27: =J27*AL$37 -> 36531.541 | ... BC27: =AA27*BC$37 -> 0 | BD27: =SUM(AE27:BC27) -> 235574.34
B28: =B27+1 -> 2038 | C28: ='Project area'!D30 -> 300 | D28: =C27 -> 300 | E28: =C26 -> 300 | F28: =C25 -> 300 | G28: =C24 -> 300 | H28: =C23 -> 300 | I28: =C22 -> 300 | J28: =C21 -> 300 | K28: =C20 -> 300 | L28: =C19 -> 300 | M28: =C18 -> 300 | N28: =C17 -> 300 | O28: =C16 -> 300 | P28: =C15 -> 62.52 | Q28: =C14 -> 36.41 | R28: =C13 -> 95.61 | S28: =C12 -> 35.19 | T28: =C11 -> 142.3 | U28: =C10 -> 69.32 | V28: =C9 -> 243.04 | W28: =C8 -> 100.9 | X28: =C7 -> 267.16 | AB28: =SUM(C28:W28) -> 4685.29 | AD28: =AD27+1 -> 2038 | AE28: =C28*AE$37 -> 90 | AF28: =D28*AF$37 -> 4078.7176 | AG28: =E28*AG$37 -> 10462.175 | AH28: =F28*AH$37 -> 16284.445 | AI28: =G28*AI$37 -> 21776.595 | AJ28: =H28*AJ$37 -> 26967.511 | AK28: =I28*AK$37 -> 31880.627 | AL28: =J28*AL$37 -> 36531.541 | ... BC28: =AA28*BC$37 -> 0 | BD28: =SUM(AE28:BC28) -> 270790.34
B29: =B28+1 -> 2039 | C29: ='Project area'!D31 -> 300 | D29: =C28 -> 300 | E29: =C27 -> 300 | F29: =C26 -> 300 | G29: =C25 -> 300 | H29: =C24 -> 300 | I29: =C23 -> 300 | J29: =C22 -> 300 | K29: =C21 -> 300 | L29: =C20 -> 300 | M29: =C19 -> 300 | N29: =C18 -> 300 | O29: =C17 -> 300 | P29: =C16 -> 300 | Q29: =C15 -> 62.52 | R29: =C14 -> 36.41 | S29: =C13 -> 95.61 | T29: =C12 -> 35.19 | U29: =C11 -> 142.3 | V29: =C10 -> 69.32 | W29: =C9 -> 243.04 | X29: =C8 -> 100.9 | Y29: =C7 -> 267.16 | AB29: =SUM(C29:W29) -> 4884.39 | AD29: =AD28+1 -> 2039 | AE29: =C29*AE$37 -> 90 | AF29: =D29*AF$37 -> 4078.7176 | AG29: =E29*AG$37 -> 10462.175 | AH29: =F29*AH$37 -> 16284.445 | AI29: =G29*AI$37 -> 21776.595 | AJ29: =H29*AJ$37 -> 26967.511 | AK29: =I29*AK$37 -> 31880.627 | AL29: =J29*AL$37 -> 36531.541 | ... BC29: =AA29*BC$37 -> 0 | BD29: =SUM(AE29:BC29) -> 303143.94
B30: =B29+1 -> 2040 | C30: ='Project area'!D32 -> 300 | D30: =C29 -> 300 | E30: =C28 -> 300 | F30: =C27 -> 300 | G30: =C26 -> 300 | H30: =C25 -> 300 | I30: =C24 -> 300 | J30: =C23 -> 300 | K30: =C22 -> 300 | L30: =C21 -> 300 | M30: =C20 -> 300 | N30: =C19 -> 300 | O30: =C18 -> 300 | P30: =C17 -> 300 | Q30: =C16 -> 300 | R30: =C15 -> 62.52 | S30: =C14 -> 36.41 | T30: =C13 -> 95.61 | U30: =C12 -> 35.19 | V30: =C11 -> 142.3 | W30: =C10 -> 69.32 | X30: =C9 -> 243.04 | Y30: =C8 -> 100.9 | Z30: =C7 -> 267.16 | AB30: =SUM(C30:W30) -> 4941.35 | AD30: =AD29+1 -> 2040 | AE30: =C30*AE$37 -> 90 | AF30: =D30*AF$37 -> 4078.7176 | AG30: =E30*AG$37 -> 10462.175 | AH30: =F30*AH$37 -> 16284.445 | AI30: =G30*AI$37 -> 21776.595 | AJ30: =H30*AJ$37 -> 26967.511 | AK30: =I30*AK$37 -> 31880.627 | AL30: =J30*AL$37 -> 36531.541 | ... BC30: =AA30*BC$37 -> 0 | BD30: =SUM(AE30:BC30) -> 347621.33
B31: =B30+1 -> 2041 | C31: ='Project area'!D33 -> 300 | D31: =C30 -> 300 | E31: =C29 -> 300 | F31: =C28 -> 300 | G31: =C27 -> 300 | H31: =C26 -> 300 | I31: =C25 -> 300 | J31: =C24 -> 300 | K31: =C23 -> 300 | L31: =C22 -> 300 | M31: =C21 -> 300 | N31: =C20 -> 300 | O31: =C19 -> 300 | P31: =C18 -> 300 | Q31: =C17 -> 300 | R31: =C16 -> 300 | S31: =C15 -> 62.52 | T31: =C14 -> 36.41 | U31: =C13 -> 95.61 | V31: =C12 -> 35.19 | W31: =C11 -> 142.3 | X31: =C10 -> 69.32 | Y31: =C9 -> 243.04 | Z31: =C8 -> 100.9 | AA31: =C7 -> 267.16 | AB31: =SUM(C31:W31) -> 5172.03 | AD31: =AD30+1 -> 2041 | AE31: =C31*AE$37 -> 90 | AF31: =D31*AF$37 -> 4078.7176 | AG31: =E31*AG$37 -> 10462.175 | AH31: =F31*AH$37 -> 16284.445 | AI31: =G31*AI$37 -> 21776.595 | AJ31: =H31*AJ$37 -> 26967.511 | AK31: =I31*AK$37 -> 31880.627 | AL31: =J31*AL$37 -> 36531.541 | ... BC31: =AA31*BC$37 -> 0 | BD31: =SUM(AE31:BC31) -> 356576.45
B32: =B31+1 -> 2042 | C32: ='Project area'!D34 -> 300 | D32: =C31 -> 300 | E32: =C30 -> 300 | F32: =C29 -> 300 | G32: =C28 -> 300 | H32: =C27 -> 300 | I32: =C26 -> 300 | J32: =C25 -> 300 | K32: =C24 -> 300 | L32: =C23 -> 300 | M32: =C22 -> 300 | N32: =C21 -> 300 | O32: =C20 -> 300 | P32: =C19 -> 300 | Q32: =C18 -> 300 | R32: =C17 -> 300 | S32: =C16 -> 300 | T32: =C15 -> 62.52 | U32: =C14 -> 36.41 | V32: =C13 -> 95.61 | W32: =C12 -> 35.19 | X32: =C11 -> 142.3 | Y32: =C10 -> 69.32 | Z32: =C9 -> 243.04 | AA32: =C8 -> 100.9 | AB32: =SUM(C32:W32) -> 5329.73 | AD32: =AD31+1 -> 2042 | AE32: =C32*AE$37 -> 90 | AF32: =D32*AF$37 -> 4078.7176 | AG32: =E32*AG$37 -> 10462.175 | AH32: =F32*AH$37 -> 16284.445 | AI32: =G32*AI$37 -> 21776.595 | AJ32: =H32*AJ$37 -> 26967.511 | AK32: =I32*AK$37 -> 31880.627 | AL32: =J32*AL$37 -> 36531.541 | ... BC32: =AA32*BC$37 -> 0 | BD32: =SUM(AE32:BC32) -> 355850.79
B33: =B32+1 -> 2043 | C33: ='Project area'!D35 -> 300 | D33: =C32 -> 300 | E33: =C31 -> 300 | F33: =C30 -> 300 | G33: =C29 -> 300 | H33: =C28 -> 300 | I33: =C27 -> 300 | J33: =C26 -> 300 | K33: =C25 -> 300 | L33: =C24 -> 300 | M33: =C23 -> 300 | N33: =C22 -> 300 | O33: =C21 -> 300 | P33: =C20 -> 300 | Q33: =C19 -> 300 | R33: =C18 -> 300 | S33: =C17 -> 300 | T33: =C16 -> 300 | U33: =C15 -> 62.52 | V33: =C14 -> 36.41 | W33: =C13 -> 95.61 | X33: =C12 -> 35.19 | Y33: =C11 -> 142.3 | Z33: =C10 -> 69.32 | AA33: =C9 -> 243.04 | AB33: =SUM(C33:W33) -> 5594.54 | AD33: =AD32+1 -> 2043 | AE33: =C33*AE$37 -> 90 | AF33: =D33*AF$37 -> 4078.7176 | AG33: =E33*AG$37 -> 10462.175 | AH33: =F33*AH$37 -> 16284.445 | AI33: =G33*AI$37 -> 21776.595 | AJ33: =H33*AJ$37 -> 26967.511 | AK33: =I33*AK$37 -> 31880.627 | AL33: =J33*AL$37 -> 36531.541 | ... BC33: =AA33*BC$37 -> 0 | BD33: =SUM(AE33:BC33) -> 338135.4
B34: =B33+1 -> 2044 | C34: ='Project area'!D36 -> 300 | D34: =C33 -> 300 | E34: =C32 -> 300 | F34: =C31 -> 300 | G34: =C30 -> 300 | H34: =C29 -> 300 | I34: =C28 -> 300 | J34: =C27 -> 300 | K34: =C26 -> 300 | L34: =C25 -> 300 | M34: =C24 -> 300 | N34: =C23 -> 300 | O34: =C22 -> 300 | P34: =C21 -> 300 | Q34: =C20 -> 300 | R34: =C19 -> 300 | S34: =C18 -> 300 | T34: =C17 -> 300 | U34: =C16 -> 300 | V34: =C15 -> 62.52 | W34: =C14 -> 36.41 | X34: =C13 -> 95.61 | Y34: =C12 -> 35.19 | Z34: =C11 -> 142.3 | AA34: =C10 -> 69.32 | AB34: =SUM(C34:W34) -> 5798.93 | AD34: =AD33+1 -> 2044 | AE34: =C34*AE$37 -> 90 | AF34: =D34*AF$37 -> 4078.7176 | AG34: =E34*AG$37 -> 10462.175 | AH34: =F34*AH$37 -> 16284.445 | AI34: =G34*AI$37 -> 21776.595 | AJ34: =H34*AJ$37 -> 26967.511 | AK34: =I34*AK$37 -> 31880.627 | AL34: =J34*AL$37 -> 36531.541 | ... BC34: =AA34*BC$37 -> 0 | BD34: =SUM(AE34:BC34) -> 346473.02
B35: =B34+1 -> 2045 | C35: ='Project area'!D37 -> 300 | D35: =C34 -> 300 | E35: =C33 -> 300 | F35: =C32 -> 300 | G35: =C31 -> 300 | H35: =C30 -> 300 | I35: =C29 -> 300 | J35: =C28 -> 300 | K35: =C27 -> 300 | L35: =C26 -> 300 | M35: =C25 -> 300 | N35: =C24 -> 300 | O35: =C23 -> 300 | P35: =C22 -> 300 | Q35: =C21 -> 300 | R35: =C20 -> 300 | S35: =C19 -> 300 | T35: =C18 -> 300 | U35: =C17 -> 300 | V35: =C16 -> 300 | W35: =C15 -> 62.52 | X35: =C14 -> 36.41 | Y35: =C13 -> 95.61 | Z35: =C12 -> 35.19 | AA35: =C11 -> 142.3 | AB35: =SUM(C35:W35) -> 6062.52 | AD35: =AD34+1 -> 2045 | AE35: =C35*AE$37 -> 90 | AF35: =D35*AF$37 -> 4078.7176 | AG35: =E35*AG$37 -> 10462.175 | AH35: =F35*AH$37 -> 16284.445 | AI35: =G35*AI$37 -> 21776.595 | AJ35: =H35*AJ$37 -> 26967.511 | AK35: =I35*AK$37 -> 31880.627 | AL35: =J35*AL$37 -> 36531.541 | ... BC35: =AA35*BC$37 -> 0 | BD35: =SUM(AE35:BC35) -> 349315.27
B36: =B35+1 -> 2046 | C36: ='Project area'!D38 -> 300 | D36: =C35 -> 300 | E36: =C34 -> 300 | F36: =C33 -> 300 | G36: =C32 -> 300 | H36: =C31 -> 300 | I36: =C30 -> 300 | J36: =C29 -> 300 | K36: =C28 -> 300 | L36: =C27 -> 300 | M36: =C26 -> 300 | N36: =C25 -> 300 | O36: =C24 -> 300 | P36: =C23 -> 300 | Q36: =C22 -> 300 | R36: =C21 -> 300 | S36: =C20 -> 300 | T36: =C19 -> 300 | U36: =C18 -> 300 | V36: =C17 -> 300 | W36: =C16 -> 300 | X36: =C15 -> 62.52 | Y36: =C14 -> 36.41 | Z36: =C13 -> 95.61 | AA36: =C12 -> 35.19 | AB36: =SUM(C36:W36) -> 6300 | AD36: =AD35+1 -> 2046 | AE36: =C36*AE$37 -> 90 | AF36: =D36*AF$37 -> 4078.7176 | AG36: =E36*AG$37 -> 10462.175 | AH36: =F36*AH$37 -> 16284.445 | AI36: =G36*AI$37 -> 21776.595 | AJ36: =H36*AJ$37 -> 26967.511 | AK36: =I36*AK$37 -> 31880.627 | AL36: =J36*AL$37 -> 36531.541 | ... BC36: =AA36*BC$37 -> 0 | BD36: =SUM(AE36:BC36) -> 369967.03
AD37: tC per ha | AE37: 0.3 | AF37: 13.595725 | AG37: 34.873916 | AH37: 54.281484 | AI37: 72.588651 | AJ37: 89.891703 | AK37: 106.26876 | AL37: 121.7718 | AM37: =AE37 -> 0.3 | AN37: =AF37 -> 13.595725 | AO37: =AG37 -> 34.873916 | AP37: =AH37 -> 54.281484 | AQ37: =AI37 -> 72.588651 | AR37: =AJ37 -> 89.891703 | AS37: =AK37 -> 106.26876 | AT37: =AL37 -> 121.7718 | ... BB37: =AT37 -> 121.7718
A40: Pine
B41: Hectares | AJ41: Carbon Stock in tC
B43: Year | C43: 0-1 | D43: 1-2 | E43: 2-3 | F43: 3-4 | G43: 4-5 | H43: 5-6 | I43: 6-7 | J43: 7-8 | K43: 8-9 | L43: 9-10 | M43: 10-11 | N43: 11-12 | O43: 12-13 | P43: 13-14 | Q43: 14-15 | R43: 15-16 | S43: 16-17 | T43: 17-18 | U43: 18-19 | V43: 19-20 | W43: 20-21 | X43: 21-22 | Y43: 22-23 | Z43: 23-24 | AA43: 24-25 | AB43: 25-26 | AC43: 26-27 | AD43: 27-28 | AE43: 28-29 | AF43: 29-30 | AG43: 30-31 | AH43: TOTAL | AJ43: Year | AK43: 0-1 | AL43: 1-2 | AM43: 2-3 | AN43: 3-4 | AO43: 4-5 | AP43: 5-6 | AQ43: 6-7 | AR43: 7-8 | AS43: 8-9 | AT43: 9-10 | AU43: 10-11 | AV43: 11-12 | AW43: 12-13 | AX43: 13-14 | AY43: 14-15 | AZ43: 15-16 | BA43: 16-17 | BB43: 17-18 | BC43: 18-19 | BD43: 19-20 | BE43: 20-21 | BF43: 21-22 | BG43: 22-23 | BH43: 23-24 | BI43: 24-25 | BJ43: 25-26 | BK43: 26-27 | BL43: 27-28 | BM43: 28-29 | BN43: 29-30 | BO43: 30-31 | BP43: TOTAL
B44: 2017 | C44: ='Project area'!E9 -> 86.79 | AH44: =SUM(C44:AG44) -> 86.79 | AJ44: 2017 | AK44: =C44*AK$74 -> 825.67614 | AL44: =D44*AL$74 -> 0 | AM44: =E44*AM$74 -> 0 | AN44: =F44*AN$74 -> 0 | AO44: =G44*AO$74 -> 0 | AP44: =H44*AP$74 -> 0 | AQ44: =I44*AQ$74 -> 0 | AR44: =J44*AR$74 -> 0 | ... BO44: =AG44*BO$74 -> 0 | BP44: =SUM(AK44:BO44) -> 825.67614
B45: 2018 | C45: ='Project area'!E10 -> 107.65 | D45: =C44 -> 86.79 | AH45: =SUM(C45:AG45) -> 194.44 | AJ45: 2018 | AK45: =C45*AK$74 -> 1024.1276 | AL45: =D45*AL$74 -> 888.60388 | AM45: =E45*AM$74 -> 0 | AN45: =F45*AN$74 -> 0 | AO45: =G45*AO$74 -> 0 | AP45: =H45*AP$74 -> 0 | AQ45: =I45*AQ$74 -> 0 | AR45: =J45*AR$74 -> 0 | ... BO45: =AG45*BO$74 -> 0 | BP45: =SUM(AK45:BO45) -> 1912.7315
...
