Workbook

Sheet Summary+Parameters
A1: Assumptions | B1: Description of the project; factors and default values used in the calculations
A2: LKG_Calculations | B2: Leakage model applying biomass/SOC assumptions to estimate leakage area and tCO₂ per year
A3: LKG_Data_Assessment | B3: Parcel‑level input table containing cropland class areas, displacement factors, and annual leakage calculations.
A4: Outgrower_Baseline | B4: Baseline land‑use classification for each outgrower plot using the year prior to planting (or same year for 2017), integrating NDVI, DynamicWorld, ESRI, and AGB to identify high‑confidence cropland.
A5: Outgrowers_Areas | B5: Final cleaned outgrower planting polygons with forested pixels (AGB ≥250 t/ha) erased using Chloris AGB to ensure only eligible non‑forest areas remain.
A6: Outgrowers_AGB | B6: Above‑ground biomass (AGB) time series per outgrower plot used to identify and mask woody/forest areas (>80 t/ha, >250 t/ha) prior to eligibility.
A7: Outgrowers_NDVI_ALL | B7: Full NDVI statistics (min/max/mean) for each outgrower plot across years used to detect cropland vegetation signatures.
A8: Leakage_Loss_Rate | B8: Annual forest‑loss rates (Hansen-based) inside the 5 km buffer used to confirm absence of project‑driven deforestation leakage.

Sheet Assumptions
A1: PROJECT INFORMATION AND ASSUMPTIONS
A3: Project Name
A4: Project Location
A5: Project Start Year
A6: Project Size (ha)
A7: Crediting Period | B7: 30
A8: VCS Project Type
A9: Methodology
A11: Variable | B11: Value | C11: Units | D11: Description | E11: Literature Reference
A12: CF | B12: 0.47 | C12: t C / t biomass | D12: Carbon fraction of dry biomass | E12: IPCC (2006) Guidelines for National Greenhouse Gas Inventories, Vol. 4, Chapter 4; AR-AM-TOOL15 v1
A13: SOC_ref | B13: 47 | C13: t C/ha | D13: Reference SOC stock for degraded grassland (0-30cm depth, Sub-Saharan Africa) | E13: IPCC (2006) Vol. 4, Chapter 2, Table 2.3; Zomer et al. (2017) SoilGrids250m
A14: b_tree | B14: 120 | C14: t/ha | D14: Above-ground tree biomass in receiving land (degraded grassland baseline) | E14: AR-AM-TOOL15 v1; Field verification
A15: b_shrub | B15: 6 | C15: t/ha | D15: Above-ground shrub biomass for degraded shrubland | E15: IPCC (2006) Vol. 4, Chapter 6; Mokany et al. (2006) Global Ecology and Biogeography 15:395-404
A16: R_tree | B16: 0.25 | C16: ratio | D16: Root:shoot ratio for trees (tropical dry forests) | E16: AR-AM-TOOL15 v1; IPCC (2006) Vol. 4, Chapter 4, Table 4.4
A17: R_shrub | B17: 0.4 | C17: ratio | D17: Root:shoot ratio for shrubs | E17: Mokany et al. (2006); IPCC (2006) Vol. 4, Chapter 6, Table 6.1
A18: CO₂_factor | B18: =44/12 -> 3.6666667 | C18: t CO₂/t C | D18: Carbon-to-CO₂ molecular weight conversion (44/12) | E18: Standard stoichiometric ratio
A19: f_lup | B19: 1 | C19: - | D19: SOC factor for pre-displacement land-use (grassland) | E19: IPCC (2006) Vol. 4, Chapter 2, Table 2.3
A20: f_mgp | B20: 0.97 | C20: - | D20: SOC factor for moderately degraded grassland management | E20: IPCC (2006) Vol. 4, Chapter 6, Table 6.2
A21: f_inp | B21: 1 | C21: - | D21: SOC factor for low/medium input levels before displacement | E21: IPCC (2006) Vol. 4, Chapter 5, Table 5.5
A22: f_lud | B22: 0.48 | C22: - | D22: SOC factor for long-term annual crops as post-displacement land use | E22: IPCC (2006) Vol. 4, Chapter 2, Table 2.3 (Cropland, Sub-Saharan Africa)
A23: f_mgd | B23: 1 | C23: - | D23: SOC factor for full tillage after displacement | E23: IPCC (2006) Vol. 4, Chapter 5, Table 5.5 (Full tillage baseline)
A24: f_ind | B24: 0.92 | C24: - | D24: SOC factor for low/medium inputs after displacement | E24: IPCC (2006) Vol. 4, Chapter 5, Table 5.5 (Medium input, tropical)
A25: Displacement_Rate_High | B25: 0.40 | C25: fraction | D25: Applied when cropland occupies ≥50% of enrolled plot area. Represents high land-use intensity where farming is the primary economic activity and household food security is more dependent on the plot. Assumes 40% of displaced agricultural activity shifts to other land (60% absorbed through intensification, off-farm income, or intercropping with project trees). | E25: Meyfroidt, P., & Lambin, E.F. (2011). Global forest transition: prospects for an end to deforestation. Proceedings of the National Academy of Sciences, 108(16), 6235-6240. Gan, J., & McCarl, B.A. (2007). Measuring transnational leakage of forest conservation. Ecological Economics, 64(2), 423-432. Murray, B.C., McCarl, B.A., & Lee, H.C. (2004). Estimating leakage from forest carbon sequestration programs. Land Economics, 80(1), 109-124.
A26: Displacement_Rate_Medium | B26: 0.30 | C26: fraction | D26: Applied when cropland 30-50% of plot area | E26: Searchinger et al. (2008) Science 319:1238-1240; Oliveira et al. (2021) Nature Sustainability 4:301-309
A27: Displacement_Rate_Low | B27: 0.20 | C27: fraction | D27: Applied when cropland 10-30% of plot area | E27: Arima et al. (2011) PNAS 108(16):6460-6465; Conservative assumption
A28: Displacement_Rate_VeryLow | B28: 0.15 | C28: fraction | D28: Applied when cropland <10% of plot area | E28: Conservative assumption based on low land-use intensity; Murray et al. (2009) Energy Policy 37:1334-1344
A29: Weighted_Displacement | B29: 0.27 | C29: fraction | D29: Area-weighted average displacement rate across all plots | E29: Calculated from plot-level classification and tiered rates
A30: Cropland_High | B30: plot-specific | C30: m² | D30: High-confidence cropland (NDVI + Dynamic World + ESRI + woody mask agreement) | E30: Sentinel-2 NDVI (ESA Copernicus, 10m); Dynamic World V1 (Brown et al. 2022); ESRI Land Cover 2017-2023 (Karra et al. 2021)
A31: Cropland_Med | B31: plot-specific | C31: m² | D31: Medium-confidence cropland (agreement across ≥2 datasets) | E31: Multi-dataset consensus classification
A32: Cropland_Low | B32: plot-specific | C32: m² | D32: Low-confidence cropland (single-dataset detection) | E32: NDVI-based cropland classification
A33: NonCropland | B33: plot-specific | C33: m² | D33: Non-cropland or woody AGB >80 t/ha | E33: Chloris AGB (Brandt et al. 2018; McNicol et al. 2018)
A34: AGB_woody_threshold | B34: 80 | C34: t/ha | D34: AGB threshold to identify woody vegetation (forest/dense shrubland) | E34: IPCC (2006) forest definition; Chloris AGB v1.2 (30m, 2007-2017)
A35: AGB_forest_threshold | B35: 250 | C35: t/ha | D35: AGB threshold used to exclude forest from outgrower plot areas | E35: Hansen GFC forest definition (≥25% canopy cover); conservative threshold for dryland forests
A36: Baseline_Year | B36: Year -1 or Year 0 | C36: YYYY | D36: Year prior to planting (Year -1) when data available; enrollment year (Year 0) for 2017 cohort or data gaps | E36: AR-AM-TOOL15 temporal baseline requirements
A37: Cropland_% | B37: calculated | C37: % | D37: Cropland share of plot area used to assign tiered displacement rate | E37: Derived from multi-dataset classification (HIGH confidence cropland / total plot area)
A38: Effective_Area | B38: plot-specific | C38: ha | D38: Total plot area available for land-use analysis | E38: Ground-truthed plot boundaries (GPS coordinates)
A39: Leakage_ha | B39: calculated | C39: ha | D39: Displaced cropland area = Effective_Area × Cropland_% × Displacement_Rate | E39: AR-AM-TOOL15 § 5.1 methodology
A40: ΔC_biomass | B40: calculated | C40: t C/ha | D40: Biomass carbon change in receiving land (displaced cropland → degraded grassland) | E40: AR-AM-TOOL15 Equation 5: CF × [(b_tree + b_shrub) × (1 + R)]
A41: ΔSOC | B41: calculated | C41: t C/ha | D41: SOC change due to land-use transition (cropland → grassland) over 20 years | E41: AR-AM-TOOL15 + IPCC (2006) SOC stock change methodology
A42: Leakage_tCO₂ | B42: calculated | C42: t CO₂ | D42: Total leakage emissions = Leakage_ha × (ΔC_biomass + ΔSOC) × 3.667 | E42: AR-AM-TOOL15 Equation 4
...

Sheet LKG_Calculations
A1: Leakage Outgrower Calculation
C7: Table 1
D8: Base_High_Confidence | E8: Sc2_HighMed | F8: Sc3_ALL | G8: Sc3_ALL_100%Disp
C9: Total_Active_Cropland_ha | D9: =G61 -> 206.41651 | E9: =AQ61 -> 799.59841 | F9: =CA61 -> 2596.2403 | G9: =DK61 -> 2596.2403
C10: %_Active_Cropland_Area | D10: =LKG_Data_Assessment!C590 -> 0.02755979 | E10: =LKG_Data_Assessment!G590 -> 0.10675873 | F10: =LKG_Data_Assessment!K590 -> 0.34663816 | G10: =LKG_Data_Assessment!K590 -> 0.34663816
C11: %_Displacement_Rate | D11: =LKG_Data_Assessment!E591 -> 0.26631588 | E11: =LKG_Data_Assessment!I591 -> 0.34298031 | F11: =LKG_Data_Assessment!M591 -> 0.36004539 | G11: 1
C12: Total_LK_Area_ha | D12: =H61 -> 64.009103 | E12: =AR61 -> 273.8593 | F12: =CB61 -> 928.25594 | G12: =DL61 -> 2596.2403
C13: Total_LK_tCO2 | D13: =I61 -> 24375.307 | E13: =AS61 -> 104964.27 | F13: =CC61 -> 354243.55 | G13: =DM61 -> 990933.68
C14: %_LK_Project_tCO2 | D14: =D13/E61 -> 0.0087204481 | E14: =E13/E61 -> 0.037551753 | F14: =F13/E61 -> 0.12673328 | G14: =G13/E61 -> 0.35451393
C15: Above_10% | D15: =IF(D14>=0.1,"Above","Negligible") -> Negligible | E15: =IF(E14>=0.1,"Above","Negligible") -> Negligible | F15: =IF(F14>=0.1,"Above","Negligible") -> Above | G15: =IF(G14>=0.1,"Above","Negligible") -> Above
I18: % Area_Cropland | J18: % LAND DISPLACED | AR18: % Area_Cropland | AS18: % LAND DISPLACED | CB18: %Area_Cropland | CC18: % LAND DISPLACED | DL18: %Area_Cropland | DM18: % LAND DISPLACED
H19: Base Scenario High Confidence | I19: =D10 -> 0.02755979 | J19: =D11 -> 0.26631588 | K19: Y1 | L19: Y2 | M19: Y3 | N19: Y4 | O19: Y5 | P19: Y6 | Q19: Y7 | R19: Y8 | S19: Y9 | T19: Y10 | U19: Y11 | V19: Y12 | W19: Y13 | X19: Y14 | Y19: Y15 | Z19: Y16 | AA19: Y17 | AB19: Y18 | AC19: Y19 | AD19: Y20 | AE19: Y21 | AF19: Y22 | AG19: Y23 | AH19: Y24 | AI19: Y25 | AJ19: Y26 | AK19: Y27 | AL19: Y28 | AM19: Y29 | AN19: Y30 | AQ19: Scenario 2 | AR19: =E10 -> 0.10675873 | AS19: =E11 -> 0.34298031 | AU19: Y1 | AV19: Y2 | AW19: Y3 | AX19: Y4 | AY19: Y5 | AZ19: Y6 | BA19: Y7 | BB19: Y8 | BC19: Y9 | CA19: Scenario 3 | CB19: =LKG_Data_Assessment!K590 -> 0.34663816 | CC19: =LKG_Data_Assessment!M591 -> 0.36004539 | CE19: Y1 | CF19: Y2 | CG19: Y3 | CH19: Y4 | CI19: Y5 | CJ19: Y6 | CK19: Y7 | CL19: Y8 | CM19: Y9 | DK19: Worst Case | DL19: =LKG_Data_Assessment!K590 -> 0.34663816 | DM19: =G11 -> 1 | DO19: Y1 | DP19: Y2 | DQ19: Y3 | DR19: Y4 | DS19: Y5 | DT19: Y6 | DU19: Y7 | DV19: Y8 | DW19: Y9
C20: Year Planting | D20: Year | E20: NFC Project tCO2 | F20: Outgorwers_ha | G20: Active_Croplands | H20: Area disp, t | I20: LK (agric, t) tCO2 | J20: ∆C( biomass,t) tC | K20: ∆SOC luc tC | L20: ∆SOC luc tC | M20: ∆SOC luc tC | N20: ∆SOC luc tC | O20: ∆SOC luc tC | P20: ∆SOC luc tC | Q20: ∆SOC luc tC | R20: ∆SOC luc tC | S20: ∆SOC luc tC | AO20: ∆SOC (luc,t) tC | AP20: % LK(t) tC02 | AQ20: Active Cropland | AR20: Area disp, t | AS20: LK (agric, t) tCO2 | AT20: ∆C( biomass,t) tC | AU20: ∆SOC luc tC | AV20: ∆SOC luc tC | AW20: ∆SOC luc tC | AX20: ∆SOC luc tC | AY20: ∆SOC luc tC | AZ20: ∆SOC luc tC | BA20: ∆SOC luc tC | BB20: ∆SOC luc tC | BC20: ∆SOC luc tC | BY20: ∆SOC (luc,t) tC | BZ20: % LK(t) tC02 | CA20: Active_Cropland | CB20: Area disp, t | CC20: LK (agric, t) tCO2 | CD20: ∆C( biomass,t) tC | CE20: ∆SOC luc tC | CF20: ∆SOC luc tC | CG20: ∆SOC luc tC | CH20: ∆SOC luc tC | CI20: ∆SOC luc tC | CJ20: ∆SOC luc tC | CK20: ∆SOC luc tC | CL20: ∆SOC luc tC | CM20: ∆SOC luc tC | DI20: ∆SOC (luc,t) tC | DJ20: % LK(t) tC02 | DK20: Active_Cropland | DL20: Area disp, t | DM20: LK (agric, t) tCO2 | DN20: ∆C( biomass,t) tC | DO20: ∆SOC luc tC | DP20: ∆SOC luc tC | DQ20: ∆SOC luc tC | DR20: ∆SOC luc tC | DS20: ∆SOC luc tC | DT20: ∆SOC luc tC | DU20: ∆SOC luc tC | DV20: ∆SOC luc tC | DW20: ∆SOC luc tC | ES20: ∆SOC (luc,t) tC | ET20: % LK(t) tC02
C21: 1 | D21: =D22-1 -> 2017 | E21: 53051.813 | F21: =LKG_Data_Assessment!B580 -> 334.20792 | G21: =LKG_Data_Assessment!C580 -> 1.7334637 | H21: =LKG_Data_Assessment!F580 -> 0.31371996 | I21: =Assumptions!$B$18*(J21+AO21) -> 95.176063 | J21: =(1.1*Assumptions!$B$14*(1+Assumptions!$B$16)+Assumptions!$B$15*(1+Assumptions!$B$17))*Assumptions!$B$12*$H21 -> 25.567549 | K21: =IF($C21<=20,Assumptions!$B$13*(Assumptions!$B$19*Assumptions!$B$20*Assumptions!$B$21-Assumptions!$B$22*Assumptions!$B$23*Assumptions!$B$24)*$H$21/20,0) -> 0.38955862 | AO21: =SUM(K21:AN21) -> 0.38955862 | AP21: =I21/E21 -> 0.0017940209 | AQ21: =LKG_Data_Assessment!G580 -> 25.787511 | AR21: =LKG_Data_Assessment!J580 -> 8.9450438 | AS21: =Assumptions!$B$18*(AT21+BY21) -> 2713.7389 | AT21: =(1.1*Assumptions!$B$14*(1+Assumptions!$B$16)+Assumptions!$B$15*(1+Assumptions!$B$17))*Assumptions!$B$12*$AR21 -> 729.00318 | AU21: =IF($C21<=20,Assumptions!$B$13*(Assumptions!$B$19*Assumptions!$B$20*Assumptions!$B$21-Assumptions!$B$22*Assumptions!$B$23*Assumptions!$B$24)*$AR$21/20,0) -> 11.107419 | BY21: =SUM(AU21:BX21) -> 11.107419 | BZ21: =AS21/E21 -> 0.051152614 | CA21: =LKG_Data_Assessment!K580 -> 102.07925 | CB21: =LKG_Data_Assessment!N580 -> 32.69233 | CC21: =Assumptions!$B$18*(CD21+DI21) -> 9918.168 | CD21: =(1.1*Assumptions!$B$14*(1+Assumptions!$B$16)+Assumptions!$B$15*(1+Assumptions!$B$17))*Assumptions!$B$12*$CB21 -> 2664.3595 | CE21: =IF($C21<=20,Assumptions!$B$13*(Assumptions!$B$19*Assumptions!$B$20*Assumptions!$B$21-Assumptions!$B$22*Assumptions!$B$23*Assumptions!$B$24)*$CB$21/20,0) -> 40.595374 | DI21: =SUM(CE21:$DH$21) -> 40.595374 | DJ21: =CC21/$E21 -> 0.18695248 | DK21: =LKG_Data_Assessment!K580 -> 102.07925 | DL21: =$DM$19*DK21 -> 102.07925 | DM21: =Assumptions!$B$18*(DN21+ES21) -> 30968.706 | DN21: =(1.1*Assumptions!$B$14*(1+Assumptions!$B$16)+Assumptions!$B$15*(1+Assumptions!$B$17))*Assumptions!$B$12*DL21 -> 8319.2548 | DO21: =IF($C21<=20,Assumptions!$B$13*(Assumptions!$B$19*Assumptions!$B$20*Assumptions!$B$21-Assumptions!$B$22*Assumptions!$B$23*Assumptions!$B$24)*$DL$21/20,0) -> 126.75589 | ES21: =SUM(DO21:ER21) -> 126.75589 | ET21: =DM21/$E21 -> 0.58374454
C22: =C21+1 -> 2 | D22: =D23-1 -> 2018 | E22: 67463.379 | F22: =LKG_Data_Assessment!B581 -> 202.22346 | G22: =LKG_Data_Assessment!C581 -> 0.55814072 | H22: =LKG_Data_Assessment!F581 -> 0.23411112 | I22: =Assumptions!$B$18*(J22+AO22) -> 72.452789 | J22: =(1.1*Assumptions!$B$14*(1+Assumptions!$B$16)+Assumptions!$B$15*(1+Assumptions!$B$17))*Assumptions!$B$12*$H22 -> 19.079588 | K22: =IF($C22<=20,Assumptions!$B$13*(Assumptions!$B$19*Assumptions!$B$20*Assumptions!$B$21-Assumptions!$B$22*Assumptions!$B$23*Assumptions!$B$24)*$H$21/20,0) -> 0.38955862 | L22: =IF($C21<=20,Assumptions!$B$13*(Assumptions!$B$19*Assumptions!$B$20*Assumptions!$B$21-Assumptions!$B$22*Assumptions!$B$23*Assumptions!$B$24)*$H$22/20,0) -> 0.29070514 | AO22: =SUM(K22:AN22) -> 0.68026376 | AP22: =I22/E22 -> 0.0010739573 | AQ22: =LKG_Data_Assessment!G581 -> 4.7075597 | AR22: =LKG_Data_Assessment!J581 -> 1.6048814 | AS22: =Assumptions!$B$18*(AT22+BY22) -> 527.61458 | AT22: =(1.1*Assumptions!$B$14*(1+Assumptions!$B$16)+Assumptions!$B$15*(1+Assumptions!$B$17))*Assumptions!$B$12*$AR22 -> 130.79462 | AU22: =IF($C22<=20,Assumptions!$B$13*(Assumptions!$B$19*Assumptions!$B$20*Assumptions!$B$21-Assumptions!$B$22*Assumptions!$B$23*Assumptions!$B$24)*$AR$21/20,0) -> 11.107419 | AV22: =IF($C21<=20,Assumptions!$B$13*(Assumptions!$B$19*Assumptions!$B$20*Assumptions!$B$21-Assumptions!$B$22*Assumptions!$B$23*Assumptions!$B$24)*$AR$22/20,0) -> 1.9928454 | BY22: =SUM(AU22:BX22) -> 13.100264 | BZ22: =AS22/E22 -> 0.0078207553 | CA22: =LKG_Data_Assessment!K581 -> 16.276716 | CB22: =LKG_Data_Assessment!N581 -> 5.6429114 | CC22: =Assumptions!$B$18*(CD22+DI22) -> 1860.7908 | CD22: =(1.1*Assumptions!$B$14*(1+Assumptions!$B$16)+Assumptions!$B$15*(1+Assumptions!$B$17))*Assumptions!$B$12*$CB22 -> 459.88599 | CE22: =IF($C22<=20,Assumptions!$B$13*(Assumptions!$B$19*Assumptions!$B$20*Assumptions!$B$21-Assumptions!$B$22*Assumptions!$B$23*Assumptions!$B$24)*$CB$21/20,0) -> 40.595374 | CF22: =IF($C21<=20,Assumptions!$B$13*(Assumptions!$B$19*Assumptions!$B$20*Assumptions!$B$21-Assumptions!$B$22*Assumptions!$B$23*Assumptions!$B$24)*$CB$22/20,0) -> 7.0070288 | DI22: =SUM(CE22:DH22) -> 47.602403 | DJ22: =CC22/$E22 -> 0.027582235 | DK22: =LKG_Data_Assessment!K581 -> 16.276716 | DL22: =$DM$19*DK22 -> 16.276716 | DM22: =Assumptions!$B$18*(DN22+ES22) -> 5402.7862 | DN22: =(1.1*Assumptions!$B$14*(1+Assumptions!$B$16)+Assumptions!$B$15*(1+Assumptions!$B$17))*Assumptions!$B$12*DL22 -> 1326.5198 | DO22: =IF($C22<=20,Assumptions!$B$13*(Assumptions!$B$19*Assumptions!$B$20*Assumptions!$B$21-Assumptions!$B$22*Assumptions!$B$23*Assumptions!$B$24)*$DL$21/20,0) -> 126.75589 | DP22: =IF($C21<=20,Assumptions!$B$13*(Assumptions!$B$19*Assumptions!$B$20*Assumptions!$B$21-Assumptions!$B$22*Assumptions!$B$23*Assumptions!$B$24)*$DL$22/20,0) -> 20.211449 | ES22: =SUM(DO22:ER22) -> 146.96734 | ET22: =DM22/$E22 -> 0.080084725
C23: =C22+1 -> 3 | D23: =D24-1 -> 2019 | E23: 78224.247 | F23: =LKG_Data_Assessment!B582 -> 183.59466 | G23: =LKG_Data_Assessment!C582 -> 1.5075567 | H23: =LKG_Data_Assessment!F582 -> 1.3233875 | I23: =Assumptions!$B$18*(J23+AO23) -> 403.98235 | J23: =(1.1*Assumptions!$B$14*(1+Assumptions!$B$16)+Assumptions!$B$15*(1+Assumptions!$B$17))*Assumptions!$B$12*$H23 -> 107.85344 | K23: =IF($C23<=20,Assumptions!$B$13*(Assumptions!$B$19*Assumptions!$B$20*Assumptions!$B$21-Assumptions!$B$22*Assumptions!$B$23*Assumptions!$B$24)*$H$21/20,0) -> 0.38955862 | L23: =IF($C22<=20,Assumptions!$B$13*(Assumptions!$B$19*Assumptions!$B$20*Assumptions!$B$21-Assumptions!$B$22*Assumptions!$B$23*Assumptions!$B$24)*$H$22/20,0) -> 0.29070514 | M23: =IF($C21<=20,Assumptions!$B$13*(Assumptions!$B$19*Assumptions!$B$20*Assumptions!$B$21-Assumptions!$B$22*Assumptions!$B$23*Assumptions!$B$24)*$H$23/20,0) -> 1.6433032 | AO23: =SUM(K23:AN23) -> 2.323567 | AP23: =I23/E23 -> 0.0051644134 | AQ23: =LKG_Data_Assessment!G582 -> 14.691968 | AR23: =LKG_Data_Assessment!J582 -> 5.3781283 | AS23: =Assumptions!$B$18*(AT23+BY23) -> 1679.6457 | AT23: =(1.1*Assumptions!$B$14*(1+Assumptions!$B$16)+Assumptions!$B$15*(1+Assumptions!$B$17))*Assumptions!$B$12*$AR23 -> 438.3067 | AU23: =IF($C23<=20,Assumptions!$B$13*(Assumptions!$B$19*Assumptions!$B$20*Assumptions!$B$21-Assumptions!$B$22*Assumptions!$B$23*Assumptions!$B$24)*$AR$21/20,0) -> 11.107419 | AV23: =IF($C22<=20,Assumptions!$B$13*(Assumptions!$B$19*Assumptions!$B$20*Assumptions!$B$21-Assumptions!$B$22*Assumptions!$B$23*Assumptions!$B$24)*$AR$22/20,0) -> 1.9928454 | AW23: =IF($C321<=20,Assumptions!$B$13*(Assumptions!$B$19*Assumptions!$B$20*Assumptions!$B$21-Assumptions!$B$22*Assumptions!$B$23*Assumptions!$B$24)*$AR$23/20,0) -> 6.6782371 | BY23: =SUM(AU23:BX23) -> 19.778501 | BZ23: =AS23/E23 -> 0.021472188 | CA23: =LKG_Data_Assessment!K582 -> 27.240675 | CB23: =LKG_Data_Assessment!N582 -> 10.020554 | CC23: =Assumptions!$B$18*(CD23+DI23) -> 3214.5684 | CD23: =(1.1*Assumptions!$B$14*(1+Assumptions!$B$16)+Assumptions!$B$15*(1+Assumptions!$B$17))*Assumptions!$B$12*$CB23 -> 816.65515 | CE23: =IF($C23<=20,Assumptions!$B$13*(Assumptions!$B$19*Assumptions!$B$20*Assumptions!$B$21-Assumptions!$B$22*Assumptions!$B$23*Assumptions!$B$24)*$CB$21/20,0) -> 40.595374 | CF23: =IF($C22<=20,Assumptions!$B$13*(Assumptions!$B$19*Assumptions!$B$20*Assumptions!$B$21-Assumptions!$B$22*Assumptions!$B$23*Assumptions!$B$24)*$CB$22/20,0) -> 7.0070288 | CG23: =IF($C21<=20,Assumptions!$B$13*(Assumptions!$B$19*Assumptions!$B$20*Assumptions!$B$21-Assumptions!$B$22*Assumptions!$B$23*Assumptions!$B$24)*$CB$23/20,0) -> 12.442923 | DI23: =SUM(CE23:DH23) -> 60.045326 | DJ23: =CC23/$E23 -> 0.041094271 | DK23: =LKG_Data_Assessment!K582 -> 27.240675 | DL23: =$DM$19*DK23 -> 27.240675 | DM23: =Assumptions!$B$18*(DN23+ES23) -> 8803.1301 | DN23: =(1.1*Assumptions!$B$14*(1+Assumptions!$B$16)+Assumptions!$B$15*(1+Assumptions!$B$17))*Assumptions!$B$12*DL23 -> 2220.0605 | DO23: =IF($C23<=20,Assumptions!$B$13*(Assumptions!$B$19*Assumptions!$B$20*Assumptions!$B$21-Assumptions!$B$22*Assumptions!$B$23*Assumptions!$B$24)*$DL$21/20,0) -> 126.75589 | DP23: =IF($C22<=20,Assumptions!$B$13*(Assumptions!$B$19*Assumptions!$B$20*Assumptions!$B$21-Assumptions!$B$22*Assumptions!$B$23*Assumptions!$B$24)*$DL$22/20,0) -> 20.211449 | DQ23: =IF($C21<=20,Assumptions!$B$13*(Assumptions!$B$19*Assumptions!$B$20*Assumptions!$B$21-Assumptions!$B$22*Assumptions!$B$23*Assumptions!$B$24)*$DL$23/20,0) -> 33.825835 | ES23: =SUM(DO23:ER23) -> 180.79317 | ET23: =DM23/$E23 -> 0.1125371
C24: =C23+1 -> 4 | D24: =D25-1 -> 2020 | E24: 94110.404 | F24: =LKG_Data_Assessment!B583 -> 95.545696 | G24: =LKG_Data_Assessment!C583 -> 6.6756018 | H24: =LKG_Data_Assessment!F583 -> 0.57053659 | I24: =Assumptions!$B$18*(J24+AO24) -> 181.60859 | J24: =(1.1*Assumptions!$B$14*(1+Assumptions!$B$16)+Assumptions!$B$15*(1+Assumptions!$B$17))*Assumptions!$B$12*$H24 -> 46.497591 | K24: =IF($C24<=20,Assumptions!$B$13*(Assumptions!$B$19*Assumptions!$B$20*Assumptions!$B$21-Assumptions!$B$22*Assumptions!$B$23*Assumptions!$B$24)*$H$21/20,0) -> 0.38955862 | L24: =IF($C23<=20,Assumptions!$B$13*(Assumptions!$B$19*Assumptions!$B$20*Assumptions!$B$21-Assumptions!$B$22*Assumptions!$B$23*Assumptions!$B$24)*$H$22/20,0) -> 0.29070514 | M24: =IF($C22<=20,Assumptions!$B$13*(Assumptions!$B$19*Assumptions!$B$20*Assumptions!$B$21-Assumptions!$B$22*Assumptions!$B$23*Assumptions!$B$24)*$H$23/20,0) -> 1.6433032 | N24: =IF($C21<=20,Assumptions!$B$13*(Assumptions!$B$19*Assumptions!$B$20*Assumptions!$B$21-Assumptions!$B$22*Assumptions!$B$23*Assumptions!$B$24)*$H$24/20,0) -> 0.7084581 | AO24: =SUM(K24:AN24) -> 3.0320251 | AP24: =I24/E24 -> 0.0019297398 | AQ24: =LKG_Data_Assessment!G583 -> 6.2352598 | AR24: =LKG_Data_Assessment!J583 -> 2.1162349 | AS24: =Assumptions!$B$18*(AT24+BY24) -> 714.5425 | AT24: =(1.1*Assumptions!$B$14*(1+Assumptions!$B$16)+Assumptions!$B$15*(1+Assumptions!$B$17))*Assumptions!$B$12*$AR24 -> 172.46891 | AU24: =IF($C24<=20,Assumptions!$B$13*(Assumptions!$B$19*Assumptions!$B$20*Assumptions!$B$21-Assumptions!$B$22*Assumptions!$B$23*Assumptions!$B$24)*$AR$21/20,0) -> 11.107419 | AV24: =IF($C23<=20,Assumptions!$B$13*(Assumptions!$B$19*Assumptions!$B$20*Assumptions!$B$21-Assumptions!$B$22*Assumptions!$B$23*Assumptions!$B$24)*$AR$22/20,0) -> 1.9928454 | AW24: =IF($C322<=20,Assumptions!$B$13*(Assumptions!$B$19*Assumptions!$B$20*Assumptions!$B$21-Assumptions!$B$22*Assumptions!$B$23*Assumptions!$B$24)*$AR$23/20,0) -> 6.6782371 | AX24: =IF($C21<=20,Assumptions!$B$13*(Assumptions!$B$19*Assumptions!$B$20*Assumptions!$B$21-Assumptions!$B$22*Assumptions!$B$23*Assumptions!$B$24)*$AR$24/20,0) -> 2.6278136 | BY24: =SUM(AU24:BX24) -> 22.406315 | BZ24: =AS24/E24 -> 0.0075925984 | CA24: =LKG_Data_Assessment!K583 -> 52.139272 | CB24: =LKG_Data_Assessment!N583 -> 16.657275 | CC24: =Assumptions!$B$18*(CD24+DI24) -> 5273.6345 | CD24: =(1.1*Assumptions!$B$14*(1+Assumptions!$B$16)+Assumptions!$B$15*(1+Assumptions!$B$17))*Assumptions!$B$12*$CB24 -> 1357.5346 | CE24: =IF($C24<=20,Assumptions!$B$13*(Assumptions!$B$19*Assumptions!$B$20*Assumptions!$B$21-Assumptions!$B$22*Assumptions!$B$23*Assumptions!$B$24)*$CB$21/20,0) -> 40.595374 | CF24: =IF($C23<=20,Assumptions!$B$13*(Assumptions!$B$19*Assumptions!$B$20*Assumptions!$B$21-Assumptions!$B$22*Assumptions!$B$23*Assumptions!$B$24)*$CB$22/20,0) -> 7.0070288 | CG24: =IF($C22<=20,Assumptions!$B$13*(Assumptions!$B$19*Assumptions!$B$20*Assumptions!$B$21-Assumptions!$B$22*Assumptions!$B$23*Assumptions!$B$24)*$CB$23/20,0) -> 12.442923 | CH24: =IF($C21<=20,Assumptions!$B$13*(Assumptions!$B$19*Assumptions!$B$20*Assumptions!$B$21-Assumptions!$B$22*Assumptions!$B$23*Assumptions!$B$24)*$CB$24/20,0) -> 20.684005 | DI24: =SUM(CE24:DH24) -> 80.729331 | DJ24: =CC24/$E24 -> 0.056036679 | DK24: =LKG_Data_Assessment!K583 -> 52.139272 | DL24: =$DM$19*DK24 -> 52.139272 | DM24: =Assumptions!$B$18*(DN24+ES24) -> 16480.871 | DN24: =(1.1*Assumptions!$B$14*(1+Assumptions!$B$16)+Assumptions!$B$15*(1+Assumptions!$B$17))*Assumptions!$B$12*DL24 -> 4249.2464 | DO24: =IF($C24<=20,Assumptions!$B$13*(Assumptions!$B$19*Assumptions!$B$20*Assumptions!$B$21-Assumptions!$B$22*Assumptions!$B$23*Assumptions!$B$24)*$DL$21/20,0) -> 126.75589 | DP24: =IF($C23<=20,Assumptions!$B$13*(Assumptions!$B$19*Assumptions!$B$20*Assumptions!$B$21-Assumptions!$B$22*Assumptions!$B$23*Assumptions!$B$24)*$DL$22/20,0) -> 20.211449 | DQ24: =IF($C22<=20,Assumptions!$B$13*(Assumptions!$B$19*Assumptions!$B$20*Assumptions!$B$21-Assumptions!$B$22*Assumptions!$B$23*Assumptions!$B$24)*$DL$23/20,0) -> 33.825835 | DR24: =IF($C21<=20,Assumptions!$B$13*(Assumptions!$B$19*Assumptions!$B$20*Assumptions!$B$21-Assumptions!$B$22*Assumptions!$B$23*Assumptions!$B$24)*$DL$24/20,0) -> 64.74342 | ES24: =SUM(DO24:ER24) -> 245.53659 | ET24: =DM24/$E24 -> 0.17512273
C25: =C24+1 -> 5 | D25: 2021 | E25: 103532.98 | F25: =LKG_Data_Assessment!B584 -> 148.73391 | G25: =LKG_Data_Assessment!C584 -> 5.26068 | H25: =LKG_Data_Assessment!F584 -> 0.65883862 | I25: =Assumptions!$B$18*(J25+AO25) -> 210.99526 | J25: =(1.1*Assumptions!$B$14*(1+Assumptions!$B$16)+Assumptions!$B$15*(1+Assumptions!$B$17))*Assumptions!$B$12*$H25 -> 53.69403 | K25: =IF($C25<=20,Assumptions!$B$13*(Assumptions!$B$19*Assumptions!$B$20*Assumptions!$B$21-Assumptions!$B$22*Assumptions!$B$23*Assumptions!$B$24)*$H$21/20,0) -> 0.38955862 | L25: =IF($C24<=20,Assumptions!$B$13*(Assumptions!$B$19*Assumptions!$B$20*Assumptions!$B$21-Assumptions!$B$22*Assumptions!$B$23*Assumptions!$B$24)*$H$22/20,0) -> 0.29070514 | M25: =IF($C23<=20,Assumptions!$B$13*(Assumptions!$B$19*Assumptions!$B$20*Assumptions!$B$21-Assumptions!$B$22*Assumptions!$B$23*Assumptions!$B$24)*$H$23/20,0) -> 1.6433032 | N25: =IF($C22<=20,Assumptions!$B$13*(Assumptions!$B$19*Assumptions!$B$20*Assumptions!$B$21-Assumptions!$B$22*Assumptions!$B$23*Assumptions!$B$24)*$H$24/20,0) -> 0.7084581 | O25: =IF($C21<=20,Assumptions!$B$13*(Assumptions!$B$19*Assumptions!$B$20*Assumptions!$B$21-Assumptions!$B$22*Assumptions!$B$23*Assumptions!$B$24)*$H$25/20,0) -> 0.81810627 | AO25: =SUM(K25:AN25) -> 3.8501314 | AP25: =I25/E25 -> 0.0020379521 | AQ25: =LKG_Data_Assessment!G584 -> 35.624209 | AR25: =LKG_Data_Assessment!J584 -> 12.078825 | AS25: =Assumptions!$B$18*(AT25+BY25) -> 3746.619 | AT25: =(1.1*Assumptions!$B$14*(1+Assumptions!$B$16)+Assumptions!$B$15*(1+Assumptions!$B$17))*Assumptions!$B$12*$AR25 -> 984.40011 | AU25: =IF($C25<=20,Assumptions!$B$13*(Assumptions!$B$19*Assumptions!$B$20*Assumptions!$B$21-Assumptions!$B$22*Assumptions!$B$23*Assumptions!$B$24)*$AR$21/20,0) -> 11.107419 | AV25: =IF($C24<=20,Assumptions!$B$13*(Assumptions!$B$19*Assumptions!$B$20*Assumptions!$B$21-Assumptions!$B$22*Assumptions!$B$23*Assumptions!$B$24)*$AR$22/20,0) -> 1.9928454 | AW25: =IF($C323<=20,Assumptions!$B$13*(Assumptions!$B$19*Assumptions!$B$20*Assumptions!$B$21-Assumptions!$B$22*Assumptions!$B$23*Assumptions!$B$24)*$AR$23/20,0) -> 6.6782371 | AX25: =IF($C22<=20,Assumptions!$B$13*(Assumptions!$B$19*Assumptions!$B$20*Assumptions!$B$21-Assumptions!$B$22*Assumptions!$B$23*Assumptions!$B$24)*$AR$24/20,0) -> 2.6278136 | AY25: =IF($C21<=20,Assumptions!$B$13*(Assumptions!$B$19*Assumptions!$B$20*Assumptions!$B$21-Assumptions!$B$22*Assumptions!$B$23*Assumptions!$B$24)*$AR$25/20,0) -> 14.998761 | BY25: =SUM(AU25:BX25) -> 37.405075 | BZ25: =AS25/E25 -> 0.036187686 | CA25: =LKG_Data_Assessment!K584 -> 63.654903 | CB25: =LKG_Data_Assessment!N584 -> 25.1607 | CC25: =Assumptions!$B$18*(CD25+DI25) -> 7929.2368 | CD25: =(1.1*Assumptions!$B$14*(1+Assumptions!$B$16)+Assumptions!$B$15*(1+Assumptions!$B$17))*Assumptions!$B$12*$CB25 -> 2050.5467 | CE25: =IF($C25<=20,Assumptions!$B$13*(Assumptions!$B$19*Assumptions!$B$20*Assumptions!$B$21-Assumptions!$B$22*Assumptions!$B$23*Assumptions!$B$24)*$CB$21/20,0) -> 40.595374 | CF25: =IF($C24<=20,Assumptions!$B$13*(Assumptions!$B$19*Assumptions!$B$20*Assumptions!$B$21-Assumptions!$B$22*Assumptions!$B$23*Assumptions!$B$24)*$CB$22/20,0) -> 7.0070288 | CG25: =IF($C23<=20,Assumptions!$B$13*(Assumptions!$B$19*Assumptions!$B$20*Assumptions!$B$21-Assumptions!$B$22*Assumptions!$B$23*Assumptions!$B$24)*$CB$23/20,0) -> 12.442923 | CH25: =IF($C22<=20,Assumptions!$B$13*(Assumptions!$B$19*Assumptions!$B$20*Assumptions!$B$21-Assumptions!$B$22*Assumptions!$B$23*Assumptions!$B$24)*$CB$24/20,0) -> 20.684005 | CI25: =IF($C21<=20,Assumptions!$B$13*(Assumptions!$B$19*Assumptions!$B$20*Assumptions!$B$21-Assumptions!$B$22*Assumptions!$B$23*Assumptions!$B$24)*$CB$25/20,0) -> 31.243048 | DI25: =SUM(CE25:DH25) -> 111.97238 | DJ25: =CC25/$E25 -> 0.076586579 | DK25: =LKG_Data_Assessment!K584 -> 63.654903 | DL25: =$DM$19*DK25 -> 63.654903 | DM25: =Assumptions!$B$18*(DN25+ES25) -> 20211.865 | DN25: =(1.1*Assumptions!$B$14*(1+Assumptions!$B$16)+Assumptions!$B$15*(1+Assumptions!$B$17))*Assumptions!$B$12*DL25 -> 5187.7473 | DO25: =IF($C25<=20,Assumptions!$B$13*(Assumptions!$B$19*Assumptions!$B$20*Assumptions!$B$21-Assumptions!$B$22*Assumptions!$B$23*Assumptions!$B$24)*$DL$21/20,0) -> 126.75589 | DP25: =IF($C24<=20,Assumptions!$B$13*(Assumptions!$B$19*Assumptions!$B$20*Assumptions!$B$21-Assumptions!$B$22*Assumptions!$B$23*Assumptions!$B$24)*$DL$22/20,0) -> 20.211449 | DQ25: =IF($C23<=20,Assumptions!$B$13*(Assumptions!$B$19*Assumptions!$B$20*Assumptions!$B$21-Assumptions!$B$22*Assumptions!$B$23*Assumptions!$B$24)*$DL$23/20,0) -> 33.825835 | DR25: =IF($C22<=20,Assumptions!$B$13*(Assumptions!$B$19*Assumptions!$B$20*Assumptions!$B$21-Assumptions!$B$22*Assumptions!$B$23*Assumptions!$B$24)*$DL$24/20,0) -> 64.74342 | DS25: =IF($C21<=20,Assumptions!$B$13*(Assumptions!$B$19*Assumptions!$B$20*Assumptions!$B$21-Assumptions!$B$22*Assumptions!$B$23*Assumptions!$B$24)*$DL$25/20,0) -> 79.042839 | ES25: =SUM(DO25:ER25) -> 324.57943 | ET25: =DM25/$E25 -> 0.19522151
C26: =C25+1 -> 6 | D26: =D25+1 -> 2022 | E26: 111249.77 | F26: =LKG_Data_Assessment!B585 -> 36.944126 | G26: =LKG_Data_Assessment!C585 -> 1.4843935 | H26: =LKG_Data_Assessment!F585 -> 0.67892596 | I26: =Assumptions!$B$18*(J26+AO26) -> 220.08906 | J26: =(1.1*Assumptions!$B$14*(1+Assumptions!$B$16)+Assumptions!$B$15*(1+Assumptions!$B$17))*Assumptions!$B$12*$H26 -> 55.331108 | K26: =IF($C26<=20,Assumptions!$B$13*(Assumptions!$B$19*Assumptions!$B$20*Assumptions!$B$21-Assumptions!$B$22*Assumptions!$B$23*Assumptions!$B$24)*$H$21/20,0) -> 0.38955862 | L26: =IF($C25<=20,Assumptions!$B$13*(Assumptions!$B$19*Assumptions!$B$20*Assumptions!$B$21-Assumptions!$B$22*Assumptions!$B$23*Assumptions!$B$24)*$H$22/20,0) -> 0.29070514 | M26: =IF($C24<=20,Assumptions!$B$13*(Assumptions!$B$19*Assumptions!$B$20*Assumptions!$B$21-Assumptions!$B$22*Assumptions!$B$23*Assumptions!$B$24)*$H$23/20,0) -> 1.6433032 | N26: =IF($C23<=20,Assumptions!$B$13*(Assumptions!$B$19*Assumptions!$B$20*Assumptions!$B$21-Assumptions!$B$22*Assumptions!$B$23*Assumptions!$B$24)*$H$24/20,0) -> 0.7084581 | O26: =IF($C22<=20,Assumptions!$B$13*(Assumptions!$B$19*Assumptions!$B$20*Assumptions!$B$21-Assumptions!$B$22*Assumptions!$B$23*Assumptions!$B$24)*$H$25/20,0) -> 0.81810627 | P26: =IF($C21<=20,Assumptions!$B$13*(Assumptions!$B$19*Assumptions!$B$20*Assumptions!$B$21-Assumptions!$B$22*Assumptions!$B$23*Assumptions!$B$24)*$H$26/20,0) -> 0.84304952 | AO26: =SUM(K26:AN26) -> 4.6931809 | AP26: =I26/E26 -> 0.0019783328 | AQ26: =LKG_Data_Assessment!G585 -> 10.434266 | AR26: =LKG_Data_Assessment!J585 -> 3.9846174 | AS26: =Assumptions!$B$18*(AT26+BY26) -> 1346.0014 | AT26: =(1.1*Assumptions!$B$14*(1+Assumptions!$B$16)+Assumptions!$B$15*(1+Assumptions!$B$17))*Assumptions!$B$12*$AR26 -> 324.73835 | AU26: =IF($C26<=20,Assumptions!$B$13*(Assumptions!$B$19*Assumptions!$B$20*Assumptions!$B$21-Assumptions!$B$22*Assumptions!$B$23*Assumptions!$B$24)*$AR$21/20,0) -> 11.107419 | AV26: =IF($C25<=20,Assumptions!$B$13*(Assumptions!$B$19*Assumptions!$B$20*Assumptions!$B$21-Assumptions!$B$22*Assumptions!$B$23*Assumptions!$B$24)*$AR$22/20,0) -> 1.9928454 | AW26: =IF($C324<=20,Assumptions!$B$13*(Assumptions!$B$19*Assumptions!$B$20*Assumptions!$B$21-Assumptions!$B$22*Assumptions!$B$23*Assumptions!$B$24)*$AR$23/20,0) -> 6.6782371 | AX26: =IF($C23<=20,Assumptions!$B$13*(Assumptions!$B$19*Assumptions!$B$20*Assumptions!$B$21-Assumptions!$B$22*Assumptions!$B$23*Assumptions!$B$24)*$AR$24/20,0) -> 2.6278136 | AY26: =IF($C22<=20,Assumptions!$B$13*(Assumptions!$B$19*Assumptions!$B$20*Assumptions!$B$21-Assumptions!$B$22*Assumptions!$B$23*Assumptions!$B$24)*$AR$25/20,0) -> 14.998761 | AZ26: =IF($C21<=20,Assumptions!$B$13*(Assumptions!$B$19*Assumptions!$B$20*Assumptions!$B$21-Assumptions!$B$22*Assumptions!$B$23*Assumptions!$B$24)*$AR$26/20,0) -> 4.9478588 | BY26: =SUM(AU26:BX26) -> 42.352934 | BZ26: =AS26/E26 -> 0.012098914 | CA26: =LKG_Data_Assessment!K585 -> 24.428849 | CB26: =LKG_Data_Assessment!N585 -> 7.4046154 | CC26: =Assumptions!$B$18*(CD26+DI26) -> 2656.9705 | CD26: =(1.1*Assumptions!$B$14*(1+Assumptions!$B$16)+Assumptions!$B$15*(1+Assumptions!$B$17))*Assumptions!$B$12*$CB26 -> 603.46134 | CE26: =IF($C26<=20,Assumptions!$B$13*(Assumptions!$B$19*Assumptions!$B$20*Assumptions!$B$21-Assumptions!$B$22*Assumptions!$B$23*Assumptions!$B$24)*$CB$21/20,0) -> 40.595374 | CF26: =IF($C25<=20,Assumptions!$B$13*(Assumptions!$B$19*Assumptions!$B$20*Assumptions!$B$21-Assumptions!$B$22*Assumptions!$B$23*Assumptions!$B$24)*$CB$22/20,0) -> 7.0070288 | CG26: =IF($C24<=20,Assumptions!$B$13*(Assumptions!$B$19*Assumptions!$B$20*Assumptions!$B$21-Assumptions!$B$22*Assumptions!$B$23*Assumptions!$B$24)*$CB$23/20,0) -> 12.442923 | CH26: =IF($C23<=20,Assumptions!$B$13*(Assumptions!$B$19*Assumptions!$B$20*Assumptions!$B$21-Assumptions!$B$22*Assumptions!$B$23*Assumptions!$B$24)*$CB$24/20,0) -> 20.684005 | CI26: =IF($C22<=20,Assumptions!$B$13*(Assumptions!$B$19*Assumptions!$B$20*Assumptions!$B$21-Assumptions!$B$22*Assumptions!$B$23*Assumptions!$B$24)*$CB$25/20,0) -> 31.243048 | CJ26: =IF($C21<=20,Assumptions!$B$13*(Assumptions!$B$19*Assumptions!$B$20*Assumptions!$B$21-Assumptions!$B$22*Assumptions!$B$23*Assumptions!$B$24)*$CB$26/20,0) -> 9.1946071 | DI26: =SUM(CE26:DH26) -> 121.16699 | DJ26: =CC26/$E26 -> 0.023882931 | DK26: =LKG_Data_Assessment!K585 -> 24.428849 | DL26: =$DM$19*DK26 -> 24.428849 | DM26: =Assumptions!$B$18*(DN26+ES26) -> 8601.3255 | DN26: =(1.1*Assumptions!$B$14*(1+Assumptions!$B$16)+Assumptions!$B$15*(1+Assumptions!$B$17))*Assumptions!$B$12*DL26 -> 1990.9023 | DO26: =IF($C26<=20,Assumptions!$B$13*(Assumptions!$B$19*Assumptions!$B$20*Assumptions!$B$21-Assumptions!$B$22*Assumptions!$B$23*Assumptions!$B$24)*$DL$21/20,0) -> 126.75589 | DP26: =IF($C25<=20,Assumptions!$B$13*(Assumptions!$B$19*Assumptions!$B$20*Assumptions!$B$21-Assumptions!$B$22*Assumptions!$B$23*Assumptions!$B$24)*$DL$22/20,0) -> 20.211449 | DQ26: =IF($C24<=20,Assumptions!$B$13*(Assumptions!$B$19*Assumptions!$B$20*Assumptions!$B$21-Assumptions!$B$22*Assumptions!$B$23*Assumptions!$B$24)*$DL$23/20,0) -> 33.825835 | DR26: =IF($C23<=20,Assumptions!$B$13*(Assumptions!$B$19*Assumptions!$B$20*Assumptions!$B$21-Assumptions!$B$22*Assumptions!$B$23*Assumptions!$B$24)*$DL$24/20,0) -> 64.74342 | DS26: =IF($C22<=20,Assumptions!$B$13*(Assumptions!$B$19*Assumptions!$B$20*Assumptions!$B$21-Assumptions!$B$22*Assumptions!$B$23*Assumptions!$B$24)*$DL$25/20,0) -> 79.042839 | DT26: =IF($C21<=20,Assumptions!$B$13*(Assumptions!$B$19*Assumptions!$B$20*Assumptions!$B$21-Assumptions!$B$22*Assumptions!$B$23*Assumptions!$B$24)*$DL$26/20,0) -> 30.334279 | ES26: =SUM(DO26:ER26) -> 354.91371 | ET26: =DM26/$E26 -> 0.077315447
C27: =C26+1 -> 7 | D27: =D26+1 -> 2023 | E27: 116697.01 | F27: =LKG_Data_Assessment!B586 -> 103.41499 | G27: =LKG_Data_Assessment!C586 -> 9.3141181 | H27: =LKG_Data_Assessment!F586 -> 0.16928704 | I27: =Assumptions!$B$18*(J27+AO27) -> 68.56647 | J27: =(1.1*Assumptions!$B$14*(1+Assumptions!$B$16)+Assumptions!$B$15*(1+Assumptions!$B$17))*Assumptions!$B$12*$H27 -> 13.796555 | K27: =IF($C27<=20,Assumptions!$B$13*(Assumptions!$B$19*Assumptions!$B$20*Assumptions!$B$21-Assumptions!$B$22*Assumptions!$B$23*Assumptions!$B$24)*$H$21/20,0) -> 0.38955862 | L27: =IF($C26<=20,Assumptions!$B$13*(Assumptions!$B$19*Assumptions!$B$20*Assumptions!$B$21-Assumptions!$B$22*Assumptions!$B$23*Assumptions!$B$24)*$H$22/20,0) -> 0.29070514 | M27: =IF($C25<=20,Assumptions!$B$13*(Assumptions!$B$19*Assumptions!$B$20*Assumptions!$B$21-Assumptions!$B$22*Assumptions!$B$23*Assumptions!$B$24)*$H$23/20,0) -> 1.6433032 | N27: =IF($C24<=20,Assumptions!$B$13*(Assumptions!$B$19*Assumptions!$B$20*Assumptions!$B$21-Assumptions!$B$22*Assumptions!$B$23*Assumptions!$B$24)*$H$24/20,0) -> 0.7084581 | O27: =IF($C23<=20,Assumptions!$B$13*(Assumptions!$B$19*Assumptions!$B$20*Assumptions!$B$21-Assumptions!$B$22*Assumptions!$B$23*Assumptions!$B$24)*$H$25/20,0) -> 0.81810627 | P27: =IF($C22<=20,Assumptions!$B$13*(Assumptions!$B$19*Assumptions!$B$20*Assumptions!$B$21-Assumptions!$B$22*Assumptions!$B$23*Assumptions!$B$24)*$H$26/20,0) -> 0.84304952 | Q27: =IF($C21<=20,Assumptions!$B$13*(Assumptions!$B$19*Assumptions!$B$20*Assumptions!$B$21-Assumptions!$B$22*Assumptions!$B$23*Assumptions!$B$24)*$H$27/20,0) -> 0.21021049 | AO27: =SUM(K27:AN27) -> 4.9033914 | AP27: =I27/E27 -> 0.00058755978 | AQ27: =LKG_Data_Assessment!G586 -> 9.3755024 | AR27: =LKG_Data_Assessment!J586 -> 2.8133493 | AS27: =Assumptions!$B$18*(AT27+BY27) -> 1008.8053 | AT27: =(1.1*Assumptions!$B$14*(1+Assumptions!$B$16)+Assumptions!$B$15*(1+Assumptions!$B$17))*Assumptions!$B$12*$AR27 -> 229.28234 | AU27: =IF($C27<=20,Assumptions!$B$13*(Assumptions!$B$19*Assumptions!$B$20*Assumptions!$B$21-Assumptions!$B$22*Assumptions!$B$23*Assumptions!$B$24)*$AR$21/20,0) -> 11.107419 | AV27: =IF($C26<=20,Assumptions!$B$13*(Assumptions!$B$19*Assumptions!$B$20*Assumptions!$B$21-Assumptions!$B$22*Assumptions!$B$23*Assumptions!$B$24)*$AR$22/20,0) -> 1.9928454 | AW27: =IF($C325<=20,Assumptions!$B$13*(Assumptions!$B$19*Assumptions!$B$20*Assumptions!$B$21-Assumptions!$B$22*Assumptions!$B$23*Assumptions!$B$24)*$AR$23/20,0) -> 6.6782371 | AX27: =IF($C24<=20,Assumptions!$B$13*(Assumptions!$B$19*Assumptions!$B$20*Assumptions!$B$21-Assumptions!$B$22*Assumptions!$B$23*Assumptions!$B$24)*$AR$24/20,0) -> 2.6278136 | AY27: =IF($C23<=20,Assumptions!$B$13*(Assumptions!$B$19*Assumptions!$B$20*Assumptions!$B$21-Assumptions!$B$22*Assumptions!$B$23*Assumptions!$B$24)*$AR$25/20,0) -> 14.998761 | AZ27: =IF($C22<=20,Assumptions!$B$13*(Assumptions!$B$19*Assumptions!$B$20*Assumptions!$B$21-Assumptions!$B$22*Assumptions!$B$23*Assumptions!$B$24)*$AR$26/20,0) -> 4.9478588 | BA27: =IF($C21<=20,Assumptions!$B$13*(Assumptions!$B$19*Assumptions!$B$20*Assumptions!$B$21-Assumptions!$B$22*Assumptions!$B$23*Assumptions!$B$24)*$AR$27/20,0) -> 3.4934483 | BY27: =SUM(AU27:BX27) -> 45.846382 | BZ27: =AS27/E27 -> 0.0086446543 | CA27: =LKG_Data_Assessment!K586 -> 62.220946 | CB27: =LKG_Data_Assessment!N586 -> 19.571187 | CC27: =Assumptions!$B$18*(CD27+DI27) -> 6381.767 | CD27: =(1.1*Assumptions!$B$14*(1+Assumptions!$B$16)+Assumptions!$B$15*(1+Assumptions!$B$17))*Assumptions!$B$12*$CB27 -> 1595.0126 | CE27: =IF($C27<=20,Assumptions!$B$13*(Assumptions!$B$19*Assumptions!$B$20*Assumptions!$B$21-Assumptions!$B$22*Assumptions!$B$23*Assumptions!$B$24)*$CB$21/20,0) -> 40.595374 | CF27: =IF($C26<=20,Assumptions!$B$13*(Assumptions!$B$19*Assumptions!$B$20*Assumptions!$B$21-Assumptions!$B$22*Assumptions!$B$23*Assumptions!$B$24)*$CB$22/20,0) -> 7.0070288 | CG27: =IF($C25<=20,Assumptions!$B$13*(Assumptions!$B$19*Assumptions!$B$20*Assumptions!$B$21-Assumptions!$B$22*Assumptions!$B$23*Assumptions!$B$24)*$CB$23/20,0) -> 12.442923 | CH27: =IF($C24<=20,Assumptions!$B$13*(Assumptions!$B$19*Assumptions!$B$20*Assumptions!$B$21-Assumptions!$B$22*Assumptions!$B$23*Assumptions!$B$24)*$CB$24/20,0) -> 20.684005 | CI27: =IF($C23<=20,Assumptions!$B$13*(Assumptions!$B$19*Assumptions!$B$20*Assumptions!$B$21-Assumptions!$B$22*Assumptions!$B$23*Assumptions!$B$24)*$CB$25/20,0) -> 31.243048 | CJ27: =IF($C22<=20,Assumptions!$B$13*(Assumptions!$B$19*Assumptions!$B$20*Assumptions!$B$21-Assumptions!$B$22*Assumptions!$B$23*Assumptions!$B$24)*$CB$26/20,0) -> 9.1946071 | CK27: =IF($C21<=20,Assumptions!$B$13*(Assumptions!$B$19*Assumptions!$B$20*Assumptions!$B$21-Assumptions!$B$22*Assumptions!$B$23*Assumptions!$B$24)*$CB$27/20,0) -> 24.302326 | DI27: =SUM(CE27:DH27) -> 145.46931 | DJ27: =CC27/$E27 -> 0.054686636 | DK27: =LKG_Data_Assessment!K586 -> 62.220946 | DL27: =$DM$19*DK27 -> 62.220946 | DM27: =Assumptions!$B$18*(DN27+ES27) -> 20177.881 | DN27: =(1.1*Assumptions!$B$14*(1+Assumptions!$B$16)+Assumptions!$B$15*(1+Assumptions!$B$17))*Assumptions!$B$12*DL27 -> 5070.8826 | DO27: =IF($C27<=20,Assumptions!$B$13*(Assumptions!$B$19*Assumptions!$B$20*Assumptions!$B$21-Assumptions!$B$22*Assumptions!$B$23*Assumptions!$B$24)*$DL$21/20,0) -> 126.75589 | DP27: =IF($C26<=20,Assumptions!$B$13*(Assumptions!$B$19*Assumptions!$B$20*Assumptions!$B$21-Assumptions!$B$22*Assumptions!$B$23*Assumptions!$B$24)*$DL$22/20,0) -> 20.211449 | DQ27: =IF($C25<=20,Assumptions!$B$13*(Assumptions!$B$19*Assumptions!$B$20*Assumptions!$B$21-Assumptions!$B$22*Assumptions!$B$23*Assumptions!$B$24)*$DL$23/20,0) -> 33.825835 | DR27: =IF($C24<=20,Assumptions!$B$13*(Assumptions!$B$19*Assumptions!$B$20*Assumptions!$B$21-Assumptions!$B$22*Assumptions!$B$23*Assumptions!$B$24)*$DL$24/20,0) -> 64.74342 | DS27: =IF($C23<=20,Assumptions!$B$13*(Assumptions!$B$19*Assumptions!$B$20*Assumptions!$B$21-Assumptions!$B$22*Assumptions!$B$23*Assumptions!$B$24)*$DL$25/20,0) -> 79.042839 | DT27: =IF($C22<=20,Assumptions!$B$13*(Assumptions!$B$19*Assumptions!$B$20*Assumptions!$B$21-Assumptions!$B$22*Assumptions!$B$23*Assumptions!$B$24)*$DL$26/20,0) -> 30.334279 | DU27: =IF($C21<=20,Assumptions!$B$13*(Assumptions!$B$19*Assumptions!$B$20*Assumptions!$B$21-Assumptions!$B$22*Assumptions!$B$23*Assumptions!$B$24)*$DL$27/20,0) -> 77.262237 | ES27: =SUM(DO27:ER27) -> 432.17595 | ET27: =DM27/$E27 -> 0.1729083
C28: =C27+1 -> 8 | D28: =D27+1 -> 2024 | E28: 108600.47 | F28: =LKG_Data_Assessment!B587 -> 39.866429 | G28: =LKG_Data_Assessment!C587 -> 4.9614672 | H28: =LKG_Data_Assessment!F587 -> 0.34125519 | I28: =Assumptions!$B$18*(J28+AO28) -> 121.50877 | J28: =(1.1*Assumptions!$B$14*(1+Assumptions!$B$16)+Assumptions!$B$15*(1+Assumptions!$B$17))*Assumptions!$B$12*$H28 -> 27.811615 | K28: =IF($C28<=20,Assumptions!$B$13*(Assumptions!$B$19*Assumptions!$B$20*Assumptions!$B$21-Assumptions!$B$22*Assumptions!$B$23*Assumptions!$B$24)*$H$21/20,0) -> 0.38955862 | L28: =IF($C27<=20,Assumptions!$B$13*(Assumptions!$B$19*Assumptions!$B$20*Assumptions!$B$21-Assumptions!$B$22*Assumptions!$B$23*Assumptions!$B$24)*$H$22/20,0) -> 0.29070514 | M28: =IF($C26<=20,Assumptions!$B$13*(Assumptions!$B$19*Assumptions!$B$20*Assumptions!$B$21-Assumptions!$B$22*Assumptions!$B$23*Assumptions!$B$24)*$H$23/20,0) -> 1.6433032 | N28: =IF($C25<=20,Assumptions!$B$13*(Assumptions!$B$19*Assumptions!$B$20*Assumptions!$B$21-Assumptions!$B$22*Assumptions!$B$23*Assumptions!$B$24)*$H$24/20,0) -> 0.7084581 | O28: =IF($C24<=20,Assumptions!$B$13*(Assumptions!$B$19*Assumptions!$B$20*Assumptions!$B$21-Assumptions!$B$22*Assumptions!$B$23*Assumptions!$B$24)*$H$25/20,0) -> 0.81810627 | P28: =IF($C23<=20,Assumptions!$B$13*(Assumptions!$B$19*Assumptions!$B$20*Assumptions!$B$21-Assumptions!$B$22*Assumptions!$B$23*Assumptions!$B$24)*$H$26/20,0) -> 0.84304952 | Q28: =IF($C22<=20,Assumptions!$B$13*(Assumptions!$B$19*Assumptions!$B$20*Assumptions!$B$21-Assumptions!$B$22*Assumptions!$B$23*Assumptions!$B$24)*$H$27/20,0) -> 0.21021049 | R28: =IF($C21<=20,Assumptions!$B$13*(Assumptions!$B$19*Assumptions!$B$20*Assumptions!$B$21-Assumptions!$B$22*Assumptions!$B$23*Assumptions!$B$24)*$H$28/20,0) -> 0.42375021 | AO28: =SUM(K28:AN28) -> 5.3271416 | AP28: =I28/E28 -> 0.0011188605 | AQ28: =LKG_Data_Assessment!G587 -> 12.012741 | AR28: =LKG_Data_Assessment!J587 -> 3.8118122 | AS28: =Assumptions!$B$18*(AT28+BY28) -> 1324.5273 | AT28: =(1.1*Assumptions!$B$14*(1+Assumptions!$B$16)+Assumptions!$B$15*(1+Assumptions!$B$17))*Assumptions!$B$12*$AR28 -> 310.65507 | AU28: =IF($C28<=20,Assumptions!$B$13*(Assumptions!$B$19*Assumptions!$B$20*Assumptions!$B$21-Assumptions!$B$22*Assumptions!$B$23*Assumptions!$B$24)*$AR$21/20,0) -> 11.107419 | AV28: =IF($C27<=20,Assumptions!$B$13*(Assumptions!$B$19*Assumptions!$B$20*Assumptions!$B$21-Assumptions!$B$22*Assumptions!$B$23*Assumptions!$B$24)*$AR$22/20,0) -> 1.9928454 | AW28: =IF($C326<=20,Assumptions!$B$13*(Assumptions!$B$19*Assumptions!$B$20*Assumptions!$B$21-Assumptions!$B$22*Assumptions!$B$23*Assumptions!$B$24)*$AR$23/20,0) -> 6.6782371 | AX28: =IF($C25<=20,Assumptions!$B$13*(Assumptions!$B$19*Assumptions!$B$20*Assumptions!$B$21-Assumptions!$B$22*Assumptions!$B$23*Assumptions!$B$24)*$AR$24/20,0) -> 2.6278136 | AY28: =IF($C24<=20,Assumptions!$B$13*(Assumptions!$B$19*Assumptions!$B$20*Assumptions!$B$21-Assumptions!$B$22*Assumptions!$B$23*Assumptions!$B$24)*$AR$25/20,0) -> 14.998761 | AZ28: =IF($C23<=20,Assumptions!$B$13*(Assumptions!$B$19*Assumptions!$B$20*Assumptions!$B$21-Assumptions!$B$22*Assumptions!$B$23*Assumptions!$B$24)*$AR$26/20,0) -> 4.9478588 | BA28: =IF($C22<=20,Assumptions!$B$13*(Assumptions!$B$19*Assumptions!$B$20*Assumptions!$B$21-Assumptions!$B$22*Assumptions!$B$23*Assumptions!$B$24)*$AR$27/20,0) -> 3.4934483 | BB28: =IF($C21<=20,Assumptions!$B$13*(Assumptions!$B$19*Assumptions!$B$20*Assumptions!$B$21-Assumptions!$B$22*Assumptions!$B$23*Assumptions!$B$24)*$AR$28/20,0) -> 4.7332797 | BY28: =SUM(AU28:BX28) -> 50.579662 | BZ28: =AS28/E28 -> 0.012196332 | CA28: =LKG_Data_Assessment!K587 -> 32.543604 | CB28: =LKG_Data_Assessment!N587 -> 12.447937 | CC28: =Assumptions!$B$18*(CD28+DI28) -> 4309.8308 | CD28: =(1.1*Assumptions!$B$14*(1+Assumptions!$B$16)+Assumptions!$B$15*(1+Assumptions!$B$17))*Assumptions!$B$12*$CB28 -> 1014.482 | CE28: =IF($C28<=20,Assumptions!$B$13*(Assumptions!$B$19*Assumptions!$B$20*Assumptions!$B$21-Assumptions!$B$22*Assumptions!$B$23*Assumptions!$B$24)*$CB$21/20,0) -> 40.595374 | CF28: =IF($C27<=20,Assumptions!$B$13*(Assumptions!$B$19*Assumptions!$B$20*Assumptions!$B$21-Assumptions!$B$22*Assumptions!$B$23*Assumptions!$B$24)*$CB$22/20,0) -> 7.0070288 | CG28: =IF($C26<=20,Assumptions!$B$13*(Assumptions!$B$19*Assumptions!$B$20*Assumptions!$B$21-Assumptions!$B$22*Assumptions!$B$23*Assumptions!$B$24)*$CB$23/20,0) -> 12.442923 | CH28: =IF($C25<=20,Assumptions!$B$13*(Assumptions!$B$19*Assumptions!$B$20*Assumptions!$B$21-Assumptions!$B$22*Assumptions!$B$23*Assumptions!$B$24)*$CB$24/20,0) -> 20.684005 | CI28: =IF($C24<=20,Assumptions!$B$13*(Assumptions!$B$19*Assumptions!$B$20*Assumptions!$B$21-Assumptions!$B$22*Assumptions!$B$23*Assumptions!$B$24)*$CB$25/20,0) -> 31.243048 | CJ28: =IF($C23<=20,Assumptions!$B$13*(Assumptions!$B$19*Assumptions!$B$20*Assumptions!$B$21-Assumptions!$B$22*Assumptions!$B$23*Assumptions!$B$24)*$CB$26/20,0) -> 9.1946071 | CK28: =IF($C22<=20,Assumptions!$B$13*(Assumptions!$B$19*Assumptions!$B$20*Assumptions!$B$21-Assumptions!$B$22*Assumptions!$B$23*Assumptions!$B$24)*$CB$27/20,0) -> 24.302326 | CL28: =IF($C21<=20,Assumptions!$B$13*(Assumptions!$B$19*Assumptions!$B$20*Assumptions!$B$21-Assumptions!$B$22*Assumptions!$B$23*Assumptions!$B$24)*$CB$28/20,0) -> 15.457102 | DI28: =SUM(CE28:DH28) -> 160.92641 | DJ28: =CC28/$E28 -> 0.039685196 | DK28: =LKG_Data_Assessment!K587 -> 32.543604 | DL28: =$DM$19*DK28 -> 32.543604 | DM28: =Assumptions!$B$18*(DN28+ES28) -> 11457.693 | DN28: =(1.1*Assumptions!$B$14*(1+Assumptions!$B$16)+Assumptions!$B$15*(1+Assumptions!$B$17))*Assumptions!$B$12*DL28 -> 2652.2387 | DO28: =IF($C28<=20,Assumptions!$B$13*(Assumptions!$B$19*Assumptions!$B$20*Assumptions!$B$21-Assumptions!$B$22*Assumptions!$B$23*Assumptions!$B$24)*$DL$21/20,0) -> 126.75589 | DP28: =IF($C27<=20,Assumptions!$B$13*(Assumptions!$B$19*Assumptions!$B$20*Assumptions!$B$21-Assumptions!$B$22*Assumptions!$B$23*Assumptions!$B$24)*$DL$22/20,0) -> 20.211449 | DQ28: =IF($C26<=20,Assumptions!$B$13*(Assumptions!$B$19*Assumptions!$B$20*Assumptions!$B$21-Assumptions!$B$22*Assumptions!$B$23*Assumptions!$B$24)*$DL$23/20,0) -> 33.825835 | DR28: =IF($C25<=20,Assumptions!$B$13*(Assumptions!$B$19*Assumptions!$B$20*Assumptions!$B$21-Assumptions!$B$22*Assumptions!$B$23*Assumptions!$B$24)*$DL$24/20,0) -> 64.74342 | DS28: =IF($C24<=20,Assumptions!$B$13*(Assumptions!$B$19*Assumptions!$B$20*Assumptions!$B$21-Assumptions!$B$22*Assumptions!$B$23*Assumptions!$B$24)*$DL$25/20,0) -> 79.042839 | DT28: =IF($C23<=20,Assumptions!$B$13*(Assumptions!$B$19*Assumptions!$B$20*Assumptions!$B$21-Assumptions!$B$22*Assumptions!$B$23*Assumptions!$B$24)*$DL$26/20,0) -> 30.334279 | DU28: =IF($C22<=20,Assumptions!$B$13*(Assumptions!$B$19*Assumptions!$B$20*Assumptions!$B$21-Assumptions!$B$22*Assumptions!$B$23*Assumptions!$B$24)*$DL$27/20,0) -> 77.262237 | DV28: =IF($C21<=20,Assumptions!$B$13*(Assumptions!$B$19*Assumptions!$B$20*Assumptions!$B$21-Assumptions!$B$22*Assumptions!$B$23*Assumptions!$B$24)*$DL$28/20,0) -> 40.410695 | ES28: =SUM(DO28:ER28) -> 472.58664 | ET28: =DM28/$E28 -> 0.10550316
C29: =C28+1 -> 9 | D29: =D28+1 -> 2025 | E29: 52520.556 | F29: =LKG_Data_Assessment!B588 -> 45.239635 | G29: =LKG_Data_Assessment!C588 -> 1.2944122 | H29: =LKG_Data_Assessment!F588 -> 0.16851098 | I29: =Assumptions!$B$18*(J29+AO29) -> 70.655553 | J29: =(1.1*Assumptions!$B$14*(1+Assumptions!$B$16)+Assumptions!$B$15*(1+Assumptions!$B$17))*Assumptions!$B$12*$H29 -> 13.733308 | K29: =IF($C29<=20,Assumptions!$B$13*(Assumptions!$B$19*Assumptions!$B$20*Assumptions!$B$21-Assumptions!$B$22*Assumptions!$B$23*Assumptions!$B$24)*$H$21/20,0) -> 0.38955862 | L29: =IF($C28<=20,Assumptions!$B$13*(Assumptions!$B$19*Assumptions!$B$20*Assumptions!$B$21-Assumptions!$B$22*Assumptions!$B$23*Assumptions!$B$24)*$H$22/20,0) -> 0.29070514 | M29: =IF($C27<=20,Assumptions!$B$13*(Assumptions!$B$19*Assumptions!$B$20*Assumptions!$B$21-Assumptions!$B$22*Assumptions!$B$23*Assumptions!$B$24)*$H$23/20,0) -> 1.6433032 | N29: =IF($C26<=20,Assumptions!$B$13*(Assumptions!$B$19*Assumptions!$B$20*Assumptions!$B$21-Assumptions!$B$22*Assumptions!$B$23*Assumptions!$B$24)*$H$24/20,0) -> 0.7084581 | O29: =IF($C25<=20,Assumptions!$B$13*(Assumptions!$B$19*Assumptions!$B$20*Assumptions!$B$21-Assumptions!$B$22*Assumptions!$B$23*Assumptions!$B$24)*$H$25/20,0) -> 0.81810627 | P29: =IF($C24<=20,Assumptions!$B$13*(Assumptions!$B$19*Assumptions!$B$20*Assumptions!$B$21-Assumptions!$B$22*Assumptions!$B$23*Assumptions!$B$24)*$H$26/20,0) -> 0.84304952 | Q29: =IF($C23<=20,Assumptions!$B$13*(Assumptions!$B$19*Assumptions!$B$20*Assumptions!$B$21-Assumptions!$B$22*Assumptions!$B$23*Assumptions!$B$24)*$H$27/20,0) -> 0.21021049 | R29: =IF($C22<=20,Assumptions!$B$13*(Assumptions!$B$19*Assumptions!$B$20*Assumptions!$B$21-Assumptions!$B$22*Assumptions!$B$23*Assumptions!$B$24)*$H$28/20,0) -> 0.42375021 | S29: =IF($C21<=20,Assumptions!$B$13*(Assumptions!$B$19*Assumptions!$B$20*Assumptions!$B$21-Assumptions!$B$22*Assumptions!$B$23*Assumptions!$B$24)*$H$29/20,0) -> 0.20924683 | AO29: =SUM(K29:AN29) -> 5.5363884 | AP29: =I29/E29 -> 0.0013452933 | AQ29: =LKG_Data_Assessment!G588 -> 8.149405 | AR29: =LKG_Data_Assessment!J588 -> 2.4447169 | AS29: =Assumptions!$B$18*(AT29+BY29) -> 927.13464 | AT29: =(1.1*Assumptions!$B$14*(1+Assumptions!$B$16)+Assumptions!$B$15*(1+Assumptions!$B$17))*Assumptions!$B$12*$AR29 -> 199.23954 | AU29: =IF($C29<=20,Assumptions!$B$13*(Assumptions!$B$19*Assumptions!$B$20*Assumptions!$B$21-Assumptions!$B$22*Assumptions!$B$23*Assumptions!$B$24)*$AR$21/20,0) -> 11.107419 | AV29: =IF($C28<=20,Assumptions!$B$13*(Assumptions!$B$19*Assumptions!$B$20*Assumptions!$B$21-Assumptions!$B$22*Assumptions!$B$23*Assumptions!$B$24)*$AR$22/20,0) -> 1.9928454 | AW29: =IF($C327<=20,Assumptions!$B$13*(Assumptions!$B$19*Assumptions!$B$20*Assumptions!$B$21-Assumptions!$B$22*Assumptions!$B$23*Assumptions!$B$24)*$AR$23/20,0) -> 6.6782371 | AX29: =IF($C26<=20,Assumptions!$B$13*(Assumptions!$B$19*Assumptions!$B$20*Assumptions!$B$21-Assumptions!$B$22*Assumptions!$B$23*Assumptions!$B$24)*$AR$24/20,0) -> 2.6278136 | AY29: =IF($C25<=20,Assumptions!$B$13*(Assumptions!$B$19*Assumptions!$B$20*Assumptions!$B$21-Assumptions!$B$22*Assumptions!$B$23*Assumptions!$B$24)*$AR$25/20,0) -> 14.998761 | AZ29: =IF($C24<=20,Assumptions!$B$13*(Assumptions!$B$19*Assumptions!$B$20*Assumptions!$B$21-Assumptions!$B$22*Assumptions!$B$23*Assumptions!$B$24)*$AR$26/20,0) -> 4.9478588 | BA29: =IF($C23<=20,Assumptions!$B$13*(Assumptions!$B$19*Assumptions!$B$20*Assumptions!$B$21-Assumptions!$B$22*Assumptions!$B$23*Assumptions!$B$24)*$AR$27/20,0) -> 3.4934483 | BB29: =IF($C22<=20,Assumptions!$B$13*(Assumptions!$B$19*Assumptions!$B$20*Assumptions!$B$21-Assumptions!$B$22*Assumptions!$B$23*Assumptions!$B$24)*$AR$28/20,0) -> 4.7332797 | BC29: =IF($C21<=20,Assumptions!$B$13*(Assumptions!$B$19*Assumptions!$B$20*Assumptions!$B$21-Assumptions!$B$22*Assumptions!$B$23*Assumptions!$B$24)*$AR$29/20,0) -> 3.0357027 | BY29: =SUM(AU29:BX29) -> 53.615365 | BZ29: =AS29/E29 -> 0.017652796 | CA29: =LKG_Data_Assessment!K588 -> 31.83575 | CB29: =LKG_Data_Assessment!N588 -> 12.383972 | CC29: =Assumptions!$B$18*(CD29+DI29) -> 4347.1012 | CD29: =(1.1*Assumptions!$B$14*(1+Assumptions!$B$16)+Assumptions!$B$15*(1+Assumptions!$B$17))*Assumptions!$B$12*$CB29 -> 1009.269 | CE29: =IF($C29<=20,Assumptions!$B$13*(Assumptions!$B$19*Assumptions!$B$20*Assumptions!$B$21-Assumptions!$B$22*Assumptions!$B$23*Assumptions!$B$24)*$CB$21/20,0) -> 40.595374 | CF29: =IF($C28<=20,Assumptions!$B$13*(Assumptions!$B$19*Assumptions!$B$20*Assumptions!$B$21-Assumptions!$B$22*Assumptions!$B$23*Assumptions!$B$24)*$CB$22/20,0) -> 7.0070288 | CG29: =IF($C27<=20,Assumptions!$B$13*(Assumptions!$B$19*Assumptions!$B$20*Assumptions!$B$21-Assumptions!$B$22*Assumptions!$B$23*Assumptions!$B$24)*$CB$23/20,0) -> 12.442923 | CH29: =IF($C26<=20,Assumptions!$B$13*(Assumptions!$B$19*Assumptions!$B$20*Assumptions!$B$21-Assumptions!$B$22*Assumptions!$B$23*Assumptions!$B$24)*$CB$24/20,0) -> 20.684005 | CI29: =IF($C25<=20,Assumptions!$B$13*(Assumptions!$B$19*Assumptions!$B$20*Assumptions!$B$21-Assumptions!$B$22*Assumptions!$B$23*Assumptions!$B$24)*$CB$25/20,0) -> 31.243048 | CJ29: =IF($C24<=20,Assumptions!$B$13*(Assumptions!$B$19*Assumptions!$B$20*Assumptions!$B$21-Assumptions!$B$22*Assumptions!$B$23*Assumptions!$B$24)*$CB$26/20,0) -> 9.1946071 | CK29: =IF($C23<=20,Assumptions!$B$13*(Assumptions!$B$19*Assumptions!$B$20*Assumptions!$B$21-Assumptions!$B$22*Assumptions!$B$23*Assumptions!$B$24)*$CB$27/20,0) -> 24.302326 | CL29: =IF($C22<=20,Assumptions!$B$13*(Assumptions!$B$19*Assumptions!$B$20*Assumptions!$B$21-Assumptions!$B$22*Assumptions!$B$23*Assumptions!$B$24)*$CB$28/20,0) -> 15.457102 | CM29: =IF($C21<=20,Assumptions!$B$13*(Assumptions!$B$19*Assumptions!$B$20*Assumptions!$B$21-Assumptions!$B$22*Assumptions!$B$23*Assumptions!$B$24)*$CB$29/20,0) -> 15.377674 | DI29: =SUM(CE29:DH29) -> 176.30409 | DJ29: =CC29/$E29 -> 0.08276952 | DK29: =LKG_Data_Assessment!K588 -> 31.83575 | DL29: =$DM$19*DK29 -> 31.83575 | DM29: =Assumptions!$B$18*(DN29+ES29) -> 11391.117 | DN29: =(1.1*Assumptions!$B$14*(1+Assumptions!$B$16)+Assumptions!$B$15*(1+Assumptions!$B$17))*Assumptions!$B$12*DL29 -> 2594.5499 | DO29: =IF($C29<=20,Assumptions!$B$13*(Assumptions!$B$19*Assumptions!$B$20*Assumptions!$B$21-Assumptions!$B$22*Assumptions!$B$23*Assumptions!$B$24)*$DL$21/20,0) -> 126.75589 | DP29: =IF($C28<=20,Assumptions!$B$13*(Assumptions!$B$19*Assumptions!$B$20*Assumptions!$B$21-Assumptions!$B$22*Assumptions!$B$23*Assumptions!$B$24)*$DL$22/20,0) -> 20.211449 | DQ29: =IF($C27<=20,Assumptions!$B$13*(Assumptions!$B$19*Assumptions!$B$20*Assumptions!$B$21-Assumptions!$B$22*Assumptions!$B$23*Assumptions!$B$24)*$DL$23/20,0) -> 33.825835 | DR29: =IF($C26<=20,Assumptions!$B$13*(Assumptions!$B$19*Assumptions!$B$20*Assumptions!$B$21-Assumptions!$B$22*Assumptions!$B$23*Assumptions!$B$24)*$DL$24/20,0) -> 64.74342 | DS29: =IF($C25<=20,Assumptions!$B$13*(Assumptions!$B$19*Assumptions!$B$20*Assumptions!$B$21-Assumptions!$B$22*Assumptions!$B$23*Assumptions!$B$24)*$DL$25/20,0) -> 79.042839 | DT29: =IF($C24<=20,Assumptions!$B$13*(Assumptions!$B$19*Assumptions!$B$20*Assumptions!$B$21-Assumptions!$B$22*Assumptions!$B$23*Assumptions!$B$24)*$DL$26/20,0) -> 30.334279 | DU29: =IF($C23<=20,Assumptions!$B$13*(Assumptions!$B$19*Assumptions!$B$20*Assumptions!$B$21-Assumptions!$B$22*Assumptions!$B$23*Assumptions!$B$24)*$DL$27/20,0) -> 77.262237 | DV29: =IF($C22<=20,Assumptions!$B$13*(Assumptions!$B$19*Assumptions!$B$20*Assumptions!$B$21-Assumptions!$B$22*Assumptions!$B$23*Assumptions!$B$24)*$DL$28/20,0) -> 40.410695 | DW29: =IF($C21<=20,Assumptions!$B$13*(Assumptions!$B$19*Assumptions!$B$20*Assumptions!$B$21-Assumptions!$B$22*Assumptions!$B$23*Assumptions!$B$24)*$DL$29/20,0) -> 39.531724 | ES29: =SUM(DO29:ER29) -> 512.11837 | ET29: =DM29/$E29 -> 0.21688874
